Workbook

Sheet はじめに
B2: パチンコ販促事業 管理ワークブック Ver.2.1
B3: Lead → Estimate → Contract → Production → Invoice → Payment → Profit を1ファイルで管理
B5: ワークフローと対応シート
B6: ① 見込み・見積 | C6: 自動見積：顧客ID選択→品目をドロップダウン→単価VLOOKUP→税込合計を自動算出
B7: ② 契約 | C7: 契約書：見積番号・顧客IDを引き継ぎ、月額・スコープ・ソース/特急/修正条項を自動生成
B8: ③ 制作（中核） | C8: 案件別収益：案件を登録。店舗名・月・外注費・粗利・実質時給を自動計算
B9: ④ 外注 | C9: 外注管理：案件IDで紐付け。外注費は案件別収益へ自動集計
B10: ⑤ 請求 | C10: 請求管理：案件IDから顧客・店舗を取得、消費税・税込合計を自動算出
B11: ⑥ 入金 | C11: 入金管理：請求番号で請求額・期限を参照。延滞/入金済を自動判定・色分け
B12: ⑦ 分析 | C12: 顧客別収益・テーマ別工数分析・月次損益・年間予測が上記データから自動集計
B13: マスタ | C13: 料金マスタ（単価・税率・全ドロップダウン）／顧客マスタ（顧客ID＝全結合キー）
B14: 色の凡例 | C14: 青字=手入力 / 黒字=計算式 / 緑字=他シート参照 / 黄背景=要入力の前提
B15: 結合キー | C15: 顧客ID（C0xx）と案件ID（J0xx）と請求番号（INV-）で全シートが連結
B16: Ver.2.1 追加マスタ | C16: Theme_Master / Event_Master / Pricing_Master の3マスタを正本として全シートに連結
B17: Pricing_Master | C17: 見積・契約・請求の単価は全てPricing_Master参照（ハードコード無し）
... B19: Event_Master | C19: 案件別収益のイベント名ドロップダウン。Event別案件分析の結合キー

Sheet Pricing_Master
A1: Pricing_Master
A2: 料金の正本。見積・契約・請求の単価はすべてここを参照（ハードコード無し）。
A3: 区分 | B3: サービス名 | C3: 単価 | D3: 目安工数
A4: 月額 | B4: ライトプラン | C4: 60000 | D4: 16
A5: 月額 | B5: スタンダードプラン | C5: 100000 | D5: 32
A6: 月額 | B6: プレミアムプラン | C6: 160000 | D6: 48
A7: 初期 | B7: オンボーディング費 | C7: 150000 | D7: 8
A8: スポット | B8: 新台入替販促パッケージ | C8: 50000 | D8: 5
A9: スポット | B9: 大型販促パッケージ | C9: 100000 | D9: 10
A10: スポット | B10: グランドオープン販促 | C10: 200000 | D10: 30
A11: 追加料金 | B11: 追加媒体 | C11: 2000 | D11: 0.5
A12: 追加料金 | B12: サイネージ追加サイズ | C12: 2000 | D12: 0.5
A13: 追加料金 | B13: 修正3回目以降 | C13: 4000 | D13: 1
A14: 追加料金 | B14: 緊急修正 | C14: 9000 | D14: 1
A15: 追加料金 | B15: 当日特急対応 | C15: 10000 | D15: 0
... A22: 追加料金 | B22: 著作権譲渡 | C22: 100000 | D22: 0

Sheet Theme_Master
A1: Theme_Master
A2: テーマの正本。案件別収益・テーマ別工数・利益分析の結合キー。
A3: Theme_Code | B3: Theme_Name | C3: Theme_Category | D3: Description
A4: T101 | B4: 新台入替 | C4: 通常販促 | D4: 新台導入の告知
A5: T102 | B5: おすすめ機種 | C5: 通常販促 | D5: 注力機種の訴求
A6: T103 | B6: 機種訴求 | C6: 通常販促 | D6: 機種カテゴリ訴求
A7: T104 | B7: 演者来店 | C7: 通常販促 | D7: ゲスト・演者来店告知
A8: T105 | B8: 景品訴求 | C8: 通常販促 | D8: 景品・賞品の訴求
A9: T106 | B9: 週末訴求 | C9: 通常販促 | D9: 週末イベント告知
A10: T107 | B10: 営業スケジュール | C10: 通常販促 | D10: 月間スケジュール
A11: T108 | B11: 取材レポート | C11: 通常販促 | D11: 取材・実戦レポート編集
A12: T109 | B12: 付加価値訴求 | C12: 通常販促 | D12: 会員特典等の価値訴求
A13: T110 | B13: 会員募集 | C13: 通常販促 | D13: アプリ・会員募集
A14: T111 | B14: 店舗設備訴求 | C14: 通常販促 | D14: 設備・環境の訴求
... A22: T999 | B22: 特注案件 | C22: 特注 | D22: 個別特注

Sheet Event_Master
A1: Event_Master
A2: イベントの正本。案件別収益のイベント名ドロップダウン／Event別分析の結合キー。
A3: Event_Category | B3: Event_Name
A4: 国民の祝日 | B4: 元日
A5: 国民の祝日 | B5: 成人の日
A6: 国民の祝日 | B6: 建国記念の日
A7: 国民の祝日 | B7: 春分の日
A8: 国民の祝日 | B8: 昭和の日
A9: 国民の祝日 | B9: 海の日
A10: 国民の祝日 | B10: 山の日
A11: 国民の祝日 | B11: 敬老の日
A12: 国民の祝日 | B12: 秋分の日
A13: 国民の祝日 | B13: スポーツの日
A14: 国民の祝日 | B14: 文化の日
... A37: 店舗イベント | B37: 店長交代

Sheet 料金マスタ
A1: 料金マスタ／各種リストマスタ
A2: 単価・税率・各ドロップダウンの参照元。ここを変更すると全シートに反映。
A3: 区分 | B3: サービス名 | C3: 単価(円) | D3: 目安h | G3: テーマ種別 | H3: 受発注種別 | I3: 案件ステータス | J3: 請求ステータス | K3: 外注先 | L3: 顧客ステータス | M3: 契約プラン | N3: 外注支払
A4: 初期 | B4: 初期構築費（オンボーディング・一回） | C4: 150000 | D4: 8 | G4: リテイナー(月次) | H4: リテイナー | I4: 受注 | J4: 未請求 | K4: 外注Aさん | L4: 継続 | M4: ライト | N4: 未払
A5: リテイナー | B5: ライトプラン（月4テーマ） | C5: 60000 | D5: 16 | G5: 新台導入 | H5: スポット | I5: 制作中 | J5: 請求済 | K5: 外注Bさん | L5: 商談中 | M5: スタンダード | N5: 支払済
A6: リテイナー | B6: スタンダードプラン（月8テーマ） | C6: 100000 | D6: 32 | G6: おすすめ機種 | I6: 確認待ち | J6: 入金済 | K6: 印刷会社X | L6: 休止 | M6: プレミアム
A7: リテイナー | B7: プレミアムプラン（月12テーマ） | C7: 160000 | D7: 48 | G7: 機種カテゴリ | I7: 完了 | K7: 撮影スタッフ | L7: 解約
A8: 超過 | B8: 超過テーマ：ライト（1テーマ） | C8: 12000 | D8: 4 | G8: Web広告 | I8: 請求済
A9: 超過 | B9: 超過テーマ：スタンダード（1テーマ） | C9: 10000 | D9: 4 | G9: LINEカード
A10: 超過 | B10: 超過テーマ：プレミアム（1テーマ） | C10: 9000 | D10: 4 | G10: 月間スケジュール
A11: スポット | B11: グランドオープン販促パッケージ | C11: 200000 | D11: 30 | G11: ゲスト来店
A12: スポット | B12: 新台入替・リニューアル販促パッケージ | C12: 150000 | D12: 24 | G12: 景品
A13: スポット | B13: 周年・創業祭パッケージ | C13: 100000 | D13: 18 | G13: 価値訴求
A14: スポット | B14: 季節キャンペーン単発（GW/お盆/年末年始等） | C14: 50000 | D14: 10 | G14: 取材レポート
A15: スポット | B15: 単発テーマ制作（1テーマ） | C15: 20000 | D15: 4 | G15: 週末
A16: スポット | B16: ゲスト来店・取材レポート編集 | C16: 30000 | D16: 5 | G16: GW
A17: スポット | B17: ロゴ・店舗ブランド構築 | C17: 80000 | D17: 12 | G17: お盆
A18: 追加 | B18: 追加媒体（1点） | C18: 2000 | D18: 0.5 | G18: クリスマス
A19: 追加 | B19: 当日対応特急（1案件・定額） | C19: 10000 | D19: 0 | G19: 年末年始
A20: 追加 | B20: 土日祝対応（1案件） | C20: 10000 | D20: 0 | G20: 周年
... A23: ソース | B23: PSD/AIデータ単体納品（1点） | C23: 15000 | D23: 0.3 | G23: グランドオープン
A24: ソース | B24: 編集可能ソース一式（案件全データ） | C24: 50000 | D24: 1
A25: ソース | B25: 著作権譲渡（1案件・目安） | C25: 100000 | D25: 0
A26: 修正 | B26: 追加修正（1回） | C26: 4000 | D26: 1
A27: 修正 | B27: 緊急修正（当日・翌日対応） | C27: 9000 | D27: 1
A29: 消費税率 | B29: 0.1
A30: 特急加算率(既定) | B30: 0.3

Sheet 顧客マスタ
A1: 顧客マスタ
A2: 全顧客の基本台帳。顧客ID は全シートの結合キー。
A3: 顧客ID | B3: 店舗名 | C3: 担当者 | D3: 連絡先 | E3: 契約プラン | F3: 月額(円) | G3: 契約開始 | H3: 最低契約(月) | I3: ステータス | J3: 備考
A4: C001 | B4: パーラー〇〇 本店 | C4: 田中 | D4: tanaka@ex.jp | E4: スタンダード | F4: 100000 | G4: 46113 | H4: 6 | I4: 継続 | J4: 主力
A5: C002 | B5: △△ホール 駅前店 | C5: 佐藤 | D5: sato@ex.jp | E5: ライト | F5: 60000 | G5: 46143 | H5: 6 | I5: 継続 | J5: 新規
A6: C003 | B6: □□会館 | C6: 鈴木 | D6: suzuki@ex.jp | E6: プレミアム | F6: 160000 | G6: 46096 | H6: 6 | I6: 継続 | J6: 最優先
A7: C004 | B7: ◇◇パチンコ | C7: 高橋 | D7: takahashi@ex.jp | E7: ライト | F7: 60000 | H7: 6 | I7: 商談中 | J7: 見込み
A17: 継続 月額合計 | F17: =SUMIFS(F4:F15,I4:I15,"継続") -> 320000

Sheet 自動見積
A1: 自動見積ジェネレーター
A3: 顧客ID | B3: C001 | C3: 店舗名 | F3: =IFERROR(VLOOKUP($B$3,顧客マスタ!$A$4:$F$15,2,FALSE()),"") -> パーラー〇〇 本店
A4: 見積番号 | B4: Q-2026-001 | C4: 発行日 | F4: 46194
A6: 品目（選択） | B6: 数量 | C6: 単価 | D6: 金額
A7: 新台入替販促パッケージ | B7: 1 | C7: =IF($A7="","",IFERROR(VLOOKUP($A7,Pricing_Master!$B$4:$D$22,2,FALSE()),0)) -> 50000 | D7: =IF($A7="","",IFERROR(VLOOKUP($A7,Pricing_Master!$B$4:$D$22,2,FALSE())*$B7,0)) -> 50000
A8: 追加媒体 | B8: 4 | C8: =IF($A8="","",IFERROR(VLOOKUP($A8,Pricing_Master!$B$4:$D$22,2,FALSE()),0)) -> 2000 | D8: =IF($A8="","",IFERROR(VLOOKUP($A8,Pricing_Master!$B$4:$D$22,2,FALSE())*$B8,0)) -> 8000
A9: PSD納品 | B9: 2 | C9: =IF($A9="","",IFERROR(VLOOKUP($A9,Pricing_Master!$B$4:$D$22,2,FALSE()),0)) -> 15000 | D9: =IF($A9="","",IFERROR(VLOOKUP($A9,Pricing_Master!$B$4:$D$22,2,FALSE())*$B9,0)) -> 30000
A10: 修正3回目以降 | B10: 1 | C10: =IF($A10="","",IFERROR(VLOOKUP($A10,Pricing_Master!$B$4:$D$22,2,FALSE()),0)) -> 4000 | D10: =IF($A10="","",IFERROR(VLOOKUP($A10,Pricing_Master!$B$4:$D$22,2,FALSE())*$B10,0)) -> 4000
C11: =IF($A11="","",IFERROR(VLOOKUP($A11,Pricing_Master!$B$4:$D$22,2,FALSE()),0)) | D11: =IF($A11="","",IFERROR(VLOOKUP($A11,Pricing_Master!$B$4:$D$22,2,FALSE())*$B11,0))
C12: =IF($A12="","",IFERROR(VLOOKUP($A12,Pricing_Master!$B$4:$D$22,2,FALSE()),0)) | D12: =IF($A12="","",IFERROR(VLOOKUP($A12,Pricing_Master!$B$4:$D$22,2,FALSE())*$B12,0))
C13: =IF($A13="","",IFERROR(VLOOKUP($A13,Pricing_Master!$B$4:$D$22,2,FALSE()),0)) | D13: =IF($A13="","",IFERROR(VLOOKUP($A13,Pricing_Master!$B$4:$D$22,2,FALSE())*$B13,0))
C14: =IF($A14="","",IFERROR(VLOOKUP($A14,Pricing_Master!$B$4:$D$22,2,FALSE()),0)) | D14: =IF($A14="","",IFERROR(VLOOKUP($A14,Pricing_Master!$B$4:$D$22,2,FALSE())*$B14,0))
C15: =IF($A15="","",IFERROR(VLOOKUP($A15,Pricing_Master!$B$4:$D$22,2,FALSE()),0)) | D15: =IF($A15="","",IFERROR(VLOOKUP($A15,Pricing_Master!$B$4:$D$22,2,FALSE())*$B15,0))
C16: =IF($A16="","",IFERROR(VLOOKUP($A16,Pricing_Master!$B$4:$D$22,2,FALSE()),0)) | D16: =IF($A16="","",IFERROR(VLOOKUP($A16,Pricing_Master!$B$4:$D$22,2,FALSE())*$B16,0))
C17: =IF($A17="","",IFERROR(VLOOKUP($A17,Pricing_Master!$B$4:$D$22,2,FALSE()),0)) | D17: =IF($A17="","",IFERROR(VLOOKUP($A17,Pricing_Master!$B$4:$D$22,2,FALSE())*$B17,0))
C18: =IF($A18="","",IFERROR(VLOOKUP($A18,Pricing_Master!$B$4:$D$22,2,FALSE()),0)) | D18: =IF($A18="","",IFERROR(VLOOKUP($A18,Pricing_Master!$B$4:$D$22,2,FALSE())*$B18,0))
C19: 小計 | D19: =SUM(D7:D18) -> 92000
A20: 特急加算率 | B20: 0 | C20: 特急加算 | D20: =ROUND(D19*B20,0) -> 0
A21: 土日祝加算(¥) | B21: 0 | C21: 土日加算 | D21: =B21 -> 0
C22: 値引き | D22: 0
C23: 課税対象 | D23: =D19+D20+D21-D22 -> 92000
C24: 消費税 | D24: =ROUND(D23*料金マスタ!$B$29,0) -> 9200
C25: 合計（税込） | D25: =D23+D24 -> 101200
A27: 確定後は『案件別収益』へ案件として登録、『契約書』へ見積番号を引き継ぐ。

Sheet 契約書
A1: 契約書ジェネレーター
A3: 契約番号 | B3: K-2026-001
A4: 参照見積番号 | B4: Q-2026-001
A5: 顧客ID | B5: C001
A6: 店舗名 | B6: =IFERROR(VLOOKUP($B$5,顧客マスタ!$A$4:$F$15,2,FALSE()),"") -> パーラー〇〇 本店
A7: 契約プラン | B7: =IFERROR(VLOOKUP($B$5,顧客マスタ!$A$4:$F$15,5,FALSE()),"") -> スタンダード
A8: 月額(税抜) | B8: =IFERROR(VLOOKUP($B$7&"プラン",Pricing_Master!$B$4:$C$22,2,FALSE()),"") -> 100000
A9: 契約日 | B9: 46194
A10: 最低契約期間(月) | B10: 6
A11: 見積合計(税込) | B11: =自動見積!$D$25 -> 101200
A13: 契約条項（自動生成）
A14: 第1条 業務範囲 | B14: 本契約は別添『スコープ定義』に定める範囲を対象とし、範囲外業務は別途料金とする。
A15: 第2条 月額・期間 | B15: =" 月額 "&TEXT(B8,"¥#,##0")&"（税抜）。最低契約期間 "&B10&"ヶ月。" -> 月額 ¥100,000（税抜）。最低契約期間 6ヶ月。
A16: 第3条 納品形態 | B16: 成果物はJPG形式での納品を原則とする。
A17: 第4条 ソースデータ | B17: PSD・AI・編集可能ソースは標準納品に含まず、別料金（料金マスタ準拠）とする。
A18: 第5条 修正 | B18: 規定回数（1テーマ2回）を超える修正は1回¥4,000、緊急修正は¥9,000とする。
A19: 第6条 特急・休日 | B19: 特急（48時間以内）は案件額の+30〜50%、土日祝対応は¥10,000または+30%を加算する。
A20: 第7条 追加 | B20: 追加媒体¥2,000/点、追加キャンペーン¥15,000/件、超過テーマはプラン別単価を適用する。
A21: 第8条 著作権 | B21: 著作権は制作者に帰属し、譲渡は別途見積（制作費の200%目安）による。
A22: 第9条 支払 | B22: 請求は月末締め、翌月末日支払いとする。

Sheet 案件別収益
A1: 案件別収益（中核台帳）
A2: 売上・粗利の元データ。外注費は『外注管理』から自動集計。
A3: 案件ID | B3: 顧客ID | C3: 店舗名 | D3: 案件名 | E3: テーマ種別 | F3: 種別 | G3: 受注日 | H3: 納期 | I3: 月 | J3: 売上(円) | K3: 外注費 | L3: 工数h | M3: 粗利 | N3: 粗利率 | O3: 実質時給 | P3: ステータス | Q3: テーマコード | R3: テーマ名 | S3: イベント名 | T3: テーマカテゴリ | U3: プラン
A4: J001 | B4: C003 | C4: =IF($B4="","",IFERROR(VLOOKUP($B4,顧客マスタ!$A$4:$F$15,2,FALSE()),"")) -> □□会館 | D4: 6月リテイナー | E4: リテイナー(月次) | F4: リテイナー | G4: 46174 | I4: =IF($G4="","",TEXT($G4,"yyyy-mm")) -> 2026-06 | J4: 160000 | K4: =SUMIFS(外注管理!$I$4:$I$60,外注管理!$B$4:$B$60,$A4) -> 0 | L4: 46 | M4: =J4-K4 -> 160000 | N4: =IF(J4=0,"",M4/J4) -> 1 | O4: =IF(L4=0,"",ROUND(M4/L4,0)) -> 3478 | P4: 完了 | R4: =IF($Q4="","",IFERROR(VLOOKUP($Q4,Theme_Master!$A$4:$B$22,2,FALSE()),"")) | T4: =IF($Q4="","",IFERROR(VLOOKUP($Q4,Theme_Master!$A$4:$C$22,3,FALSE()),"")) | U4: =IF($B4="","",IFERROR(VLOOKUP($B4,顧客マスタ!$A$4:$E$15,5,FALSE()),"")) -> プレミアム
A5: J002 | B5: C001 | C5: =IF($B5="","",IFERROR(VLOOKUP($B5,顧客マスタ!$A$4:$F$15,2,FALSE()),"")) -> パーラー〇〇 本店 | D5: 6月リテイナー | E5: リテイナー(月次) | F5: リテイナー | G5: 46174 | I5: =IF($G5="","",TEXT($G5,"yyyy-mm")) -> 2026-06 | J5: 100000 | K5: =SUMIFS(外注管理!$I$4:$I$60,外注管理!$B$4:$B$60,$A5) -> 0 | L5: 30 | M5: =J5-K5 -> 100000 | N5: =IF(J5=0,"",M5/J5) -> 1 | O5: =IF(L5=0,"",ROUND(M5/L5,0)) -> 3333 | P5: 完了 | R5: =IF($Q5="","",IFERROR(VLOOKUP($Q5,Theme_Master!$A$4:$B$22,2,FALSE()),"")) | T5: =IF($Q5="","",IFERROR(VLOOKUP($Q5,Theme_Master!$A$4:$C$22,3,FALSE()),"")) | U5: =IF($B5="","",IFERROR(VLOOKUP($B5,顧客マスタ!$A$4:$E$15,5,FALSE()),"")) -> スタンダード
A6: J003 | B6: C002 | C6: =IF($B6="","",IFERROR(VLOOKUP($B6,顧客マスタ!$A$4:$F$15,2,FALSE()),"")) -> △△ホール 駅前店 | D6: 6月リテイナー | E6: リテイナー(月次) | F6: リテイナー | G6: 46174 | I6: =IF($G6="","",TEXT($G6,"yyyy-mm")) -> 2026-06 | J6: 60000 | K6: =SUMIFS(外注管理!$I$4:$I$60,外注管理!$B$4:$B$60,$A6) -> 0 | L6: 15 | M6: =J6-K6 -> 60000 | N6: =IF(J6=0,"",M6/J6) -> 1 | O6: =IF(L6=0,"",ROUND(M6/L6,0)) -> 4000 | P6: 完了 | R6: =IF($Q6="","",IFERROR(VLOOKUP($Q6,Theme_Master!$A$4:$B$22,2,FALSE()),"")) | T6: =IF($Q6="","",IFERROR(VLOOKUP($Q6,Theme_Master!$A$4:$C$22,3,FALSE()),"")) | U6: =IF($B6="","",IFERROR(VLOOKUP($B6,顧客マスタ!$A$4:$E$15,5,FALSE()),"")) -> ライト
A7: J004 | B7: C003 | C7: =IF($B7="","",IFERROR(VLOOKUP($B7,顧客マスタ!$A$4:$F$15,2,FALSE()),"")) -> □□会館 | D7: リニューアル販促一式 | E7: リニューアル | F7: スポット | G7: 46178 | H7: 46185 | I7: =IF($G7="","",TEXT($G7,"yyyy-mm")) -> 2026-06 | J7: 150000 | K7: =SUMIFS(外注管理!$I$4:$I$60,外注管理!$B$4:$B$60,$A7) -> 10000 | L7: 24 | M7: =J7-K7 -> 140000 | N7: =IF(J7=0,"",M7/J7) -> 0.93333333 | O7: =IF(L7=0,"",ROUND(M7/L7,0)) -> 5833 | P7: 請求済 | Q7: T204 | R7: =IF($Q7="","",IFERROR(VLOOKUP($Q7,Theme_Master!$A$4:$B$22,2,FALSE()),"")) -> リニューアルオープン | S7: GW | T7: =IF($Q7="","",IFERROR(VLOOKUP($Q7,Theme_Master!$A$4:$C$22,3,FALSE()),"")) -> オープン・大型 | U7: =IF($B7="","",IFERROR(VLOOKUP($B7,顧客マスタ!$A$4:$E$15,5,FALSE()),"")) -> プレミアム
A8: J005 | B8: C001 | C8: =IF($B8="","",IFERROR(VLOOKUP($B8,顧客マスタ!$A$4:$F$15,2,FALSE()),"")) -> パーラー〇〇 本店 | D8: 周年祭パッケージ | E8: 周年 | F8: スポット | G8: 46188 | H8: 46195 | I8: =IF($G8="","",TEXT($G8,"yyyy-mm")) -> 2026-06 | J8: 100000 | K8: =SUMIFS(外注管理!$I$4:$I$60,外注管理!$B$4:$B$60,$A8) -> 12000 | L8: 18 | M8: =J8-K8 -> 88000 | N8: =IF(J8=0,"",M8/J8) -> 0.88 | O8: =IF(L8=0,"",ROUND(M8/L8,0)) -> 4889 | P8: 制作中 | Q8: T201 | R8: =IF($Q8="","",IFERROR(VLOOKUP($Q8,Theme_Master!$A$4:$B$22,2,FALSE()),"")) -> 周年 | S8: お盆 | T8: =IF($Q8="","",IFERROR(VLOOKUP($Q8,Theme_Master!$A$4:$C$22,3,FALSE()),"")) -> オープン・大型 | U8: =IF($B8="","",IFERROR(VLOOKUP($B8,顧客マスタ!$A$4:$E$15,5,FALSE()),"")) -> スタンダード
A9: J006 | B9: C001 | C9: =IF($B9="","",IFERROR(VLOOKUP($B9,顧客マスタ!$A$4:$F$15,2,FALSE()),"")) -> パーラー〇〇 本店 | D9: 5月リテイナー | E9: リテイナー(月次) | F9: リテイナー | G9: 46143 | I9: =IF($G9="","",TEXT($G9,"yyyy-mm")) -> 2026-05 | J9: 100000 | K9: =SUMIFS(外注管理!$I$4:$I$60,外注管理!$B$4:$B$60,$A9) -> 0 | L9: 30 | M9: =J9-K9 -> 100000 | N9: =IF(J9=0,"",M9/J9) -> 1 | O9: =IF(L9=0,"",ROUND(M9/L9,0)) -> 3333 | P9: 請求済 | R9: =IF($Q9="","",IFERROR(VLOOKUP($Q9,Theme_Master!$A$4:$B$22,2,FALSE()),"")) | T9: =IF($Q9="","",IFERROR(VLOOKUP($Q9,Theme_Master!$A$4:$C$22,3,FALSE()),"")) | U9: =IF($B9="","",IFERROR(VLOOKUP($B9,顧客マスタ!$A$4:$E$15,5,FALSE()),"")) -> スタンダード
A10: J007 | B10: C003 | C10: =IF($B10="","",IFERROR(VLOOKUP($B10,顧客マスタ!$A$4:$F$15,2,FALSE()),"")) -> □□会館 | D10: 5月リテイナー | E10: リテイナー(月次) | F10: リテイナー | G10: 46143 | I10: =IF($G10="","",TEXT($G10,"yyyy-mm")) -> 2026-05 | J10: 160000 | K10: =SUMIFS(外注管理!$I$4:$I$60,外注管理!$B$4:$B$60,$A10) -> 0 | L10: 44 | M10: =J10-K10 -> 160000 | N10: =IF(J10=0,"",M10/J10) -> 1 | O10: =IF(L10=0,"",ROUND(M10/L10,0)) -> 3636 | P10: 請求済 | R10: =IF($Q10="","",IFERROR(VLOOKUP($Q10,Theme_Master!$A$4:$B$22,2,FALSE()),"")) | T10: =IF($Q10="","",IFERROR(VLOOKUP($Q10,Theme_Master!$A$4:$C$22,3,FALSE()),"")) | U10: =IF($B10="","",IFERROR(VLOOKUP($B10,顧客マスタ!$A$4:$E$15,5,FALSE()),"")) -> プレミアム
C11: =IF($B11="","",IFERROR(VLOOKUP($B11,顧客マスタ!$A$4:$F$15,2,FALSE()),"")) | I11: =IF($G11="","",TEXT($G11,"yyyy-mm")) | K11: =IF($A11="","",SUMIFS(外注管理!$I$4:$I$60,外注管理!$B$4:$B$60,$A11)) | M11: =IF($J11="","",J11-K11) | N11: =IF(OR($J11="",$J11=0),"",M11/J11) | O11: =IF(OR($L11="",$L11=0),"",ROUND(M11/L11,0)) | R11: =IF($Q11="","",IFERROR(VLOOKUP($Q11,Theme_Master!$A$4:$B$22,2,FALSE()),"")) | T11: =IF($Q11="","",IFERROR(VLOOKUP($Q11,Theme_Master!$A$4:$C$22,3,FALSE()),"")) | U11: =IF($B11="","",IFERROR(VLOOKUP($B11,顧客マスタ!$A$4:$E$15,5,FALSE()),""))
C12: =IF($B12="","",IFERROR(VLOOKUP($B12,顧客マスタ!$A$4:$F$15,2,FALSE()),"")) | I12: =IF($G12="","",TEXT($G12,"yyyy-mm")) | K12: =IF($A12="","",SUMIFS(外注管理!$I$4:$I$60,外注管理!$B$4:$B$60,$A12)) | M12: =IF($J12="","",J12-K12) | N12: =IF(OR($J12="",$J12=0),"",M12/J12) | O12: =IF(OR($L12="",$L12=0),"",ROUND(M12/L12,0)) | R12: =IF($Q12="","",IFERROR(VLOOKUP($Q12,Theme_Master!$A$4:$B$22,2,FALSE()),"")) | T12: =IF($Q12="","",IFERROR(VLOOKUP($Q12,Theme_Master!$A$4:$C$22,3,FALSE()),"")) | U12: =IF($B12="","",IFERROR(VLOOKUP($B12,顧客マスタ!$A$4:$E$15,5,FALSE()),""))
C13: =IF($B13="","",IFERROR(VLOOKUP($B13,顧客マスタ!$A$4:$F$15,2,FALSE()),"")) | I13: =IF($G13="","",TEXT($G13,"yyyy-mm")) | K13: =IF($A13="","",SUMIFS(外注管理!$I$4:$I$60,外注管理!$B$4:$B$60,$A13)) | M13: =IF($J13="","",J13-K13) | N13: =IF(OR($J13="",$J13=0),"",M13/J13) | O13: =IF(OR($L13="",$L13=0),"",ROUND(M13/L13,0)) | R13: =IF($Q13="","",IFERROR(VLOOKUP($Q13,Theme_Master!$A$4:$B$22,2,FALSE()),"")) | T13: =IF($Q13="","",IFERROR(VLOOKUP($Q13,Theme_Master!$A$4:$C$22,3,FALSE()),"")) | U13: =IF($B13="","",IFERROR(VLOOKUP($B13,顧客マスタ!$A$4:$E$15,5,FALSE()),""))
C14: =IF($B14="","",IFERROR(VLOOKUP($B14,顧客マスタ!$A$4:$F$15,2,FALSE()),"")) | I14: =IF($G14="","",TEXT($G14,"yyyy-mm")) | K14: =IF($A14="","",SUMIFS(外注管理!$I$4:$I$60,外注管理!$B$4:$B$60,$A14)) | M14: =IF($J14="","",J14-K14) | N14: =IF(OR($J14="",$J14=0),"",M14/J14) | O14: =IF(OR($L14="",$L14=0),"",ROUND(M14/L14,0)) | R14: =IF($Q14="","",IFERROR(VLOOKUP($Q14,Theme_Master!$A$4:$B$22,2,FALSE()),"")) | T14: =IF($Q14="","",IFERROR(VLOOKUP($Q14,Theme_Master!$A$4:$C$22,3,FALSE()),"")) | U14: =IF($B14="","",IFERROR(VLOOKUP($B14,顧客マスタ!$A$4:$E$15,5,FALSE()),""))
C15: =IF($B15="","",IFERROR(VLOOKUP($B15,顧客マスタ!$A$4:$F$15,2,FALSE()),"")) | I15: =IF($G15="","",TEXT($G15,"yyyy-mm")) | K15: =IF($A15="","",SUMIFS(外注管理!$I$4:$I$60,外注管理!$B$4:$B$60,$A15)) | M15: =IF($J15="","",J15-K15) | N15: =IF(OR($J15="",$J15=0),"",M15/J15) | O15: =IF(OR($L15="",$L15=0),"",ROUND(M15/L15,0)) | R15: =IF($Q15="","",IFERROR(VLOOKUP($Q15,Theme_Master!$A$4:$B$22,2,FALSE()),"")) | T15: =IF($Q15="","",IFERROR(VLOOKUP($Q15,Theme_Master!$A$4:$C$22,3,FALSE()),"")) | U15: =IF($B15="","",IFERROR(VLOOKUP($B15,顧客マスタ!$A$4:$E$15,5,FALSE()),""))
C16: =IF($B16="","",IFERROR(VLOOKUP($B16,顧客マスタ!$A$4:$F$15,2,FALSE()),"")) | I16: =IF($G16="","",TEXT($G16,"yyyy-mm")) | K16: =IF($A16="","",SUMIFS(外注管理!$I$4:$I$60,外注管理!$B$4:$B$60,$A16)) | M16: =IF($J16="","",J16-K16) | N16: =IF(OR($J16="",$J16=0),"",M16/J16) | O16: =IF(OR($L16="",$L16=0),"",ROUND(M16/L16,0)) | R16: =IF($Q16="","",IFERROR(VLOOKUP($Q16,Theme_Master!$A$4:$B$22,2,FALSE()),"")) | T16: =IF($Q16="","",IFERROR(VLOOKUP($Q16,Theme_Master!$A$4:$C$22,3,FALSE()),"")) | U16: =IF($B16="","",IFERROR(VLOOKUP($B16,顧客マスタ!$A$4:$E$15,5,FALSE()),""))
C17: =IF($B17="","",IFERROR(VLOOKUP($B17,顧客マスタ!$A$4:$F$15,2,FALSE()),"")) | I17: =IF($G17="","",TEXT($G17,"yyyy-mm")) | K17: =IF($A17="","",SUMIFS(外注管理!$I$4:$I$60,外注管理!$B$4:$B$60,$A17)) | M17: =IF($J17="","",J17-K17) | N17: =IF(OR($J17="",$J17=0),"",M17/J17) | O17: =IF(OR($L17="",$L17=0),"",ROUND(M17/L17,0)) | R17: =IF($Q17="","",IFERROR(VLOOKUP($Q17,Theme_Master!$A$4:$B$22,2,FALSE()),"")) | T17: =IF($Q17="","",IFERROR(VLOOKUP($Q17,Theme_Master!$A$4:$C$22,3,FALSE()),"")) | U17: =IF($B17="","",IFERROR(VLOOKUP($B17,顧客マスタ!$A$4:$E$15,5,FALSE()),""))
C18: =IF($B18="","",IFERROR(VLOOKUP($B18,顧客マスタ!$A$4:$F$15,2,FALSE()),"")) | I18: =IF($G18="","",TEXT($G18,"yyyy-mm")) | K18: =IF($A18="","",SUMIFS(外注管理!$I$4:$I$60,外注管理!$B$4:$B$60,$A18)) | M18: =IF($J18="","",J18-K18) | N18: =IF(OR($J18="",$J18=0),"",M18/J18) | O18: =IF(OR($L18="",$L18=0),"",ROUND(M18/L18,0)) | R18: =IF($Q18="","",IFERROR(VLOOKUP($Q18,Theme_Master!$A$4:$B$22,2,FALSE()),"")) | T18: =IF($Q18="","",IFERROR(VLOOKUP($Q18,Theme_Master!$A$4:$C$22,3,FALSE()),"")) | U18: =IF($B18="","",IFERROR(VLOOKUP($B18,顧客マスタ!$A$4:$E$15,5,FALSE()),""))
C19: =IF($B19="","",IFERROR(VLOOKUP($B19,顧客マスタ!$A$4:$F$15,2,FALSE()),"")) | I19: =IF($G19="","",TEXT($G19,"yyyy-mm")) | K19: =IF($A19="","",SUMIFS(外注管理!$I$4:$I$60,外注管理!$B$4:$B$60,$A19)) | M19: =IF($J19="","",J19-K19) | N19: =IF(OR($J19="",$J19=0),"",M19/J19) | O19: =IF(OR($L19="",$L19=0),"",ROUND(M19/L19,0)) | R19: =IF($Q19="","",IFERROR(VLOOKUP($Q19,Theme_Master!$A$4:$B$22,2,FALSE()),"")) | T19: =IF($Q19="","",IFERROR(VLOOKUP($Q19,Theme_Master!$A$4:$C$22,3,FALSE()),"")) | U19: =IF($B19="","",IFERROR(VLOOKUP($B19,顧客マスタ!$A$4:$E$15,5,FALSE()),""))
C20: =IF($B20="","",IFERROR(VLOOKUP($B20,顧客マスタ!$A$4:$F$15,2,FALSE()),"")) | I20: =IF($G20="","",TEXT($G20,"yyyy-mm")) | K20: =IF($A20="","",SUMIFS(外注管理!$I$4:$I$60,外注管理!$B$4:$B$60,$A20)) | M20: =IF($J20="","",J20-K20) | N20: =IF(OR($J20="",$J20=0),"",M20/J20) | O20: =IF(OR($L20="",$L20=0),"",ROUND(M20/L20,0)) | R20: =IF($Q20="","",IFERROR(VLOOKUP($Q20,Theme_Master!$A$4:$B$22,2,FALSE()),"")) | T20: =IF($Q20="","",IFERROR(VLOOKUP($Q20,Theme_Master!$A$4:$C$22,3,FALSE()),"")) | U20: =IF($B20="","",IFERROR(VLOOKUP($B20,顧客マスタ!$A$4:$E$15,5,FALSE()),""))
C21: =IF($B21="","",IFERROR(VLOOKUP($B21,顧客マスタ!$A$4:$F$15,2,FALSE()),"")) | I21: =IF($G21="","",TEXT($G21,"yyyy-mm")) | K21: =IF($A21="","",SUMIFS(外注管理!$I$4:$I$60,外注管理!$B$4:$B$60,$A21)) | M21: =IF($J21="","",J21-K21) | N21: =IF(OR($J21="",$J21=0),"",M21/J21) | O21: =IF(OR($L21="",$L21=0),"",ROUND(M21/L21,0)) | R21: =IF($Q21="","",IFERROR(VLOOKUP($Q21,Theme_Master!$A$4:$B$22,2,FALSE()),"")) | T21: =IF($Q21="","",IFERROR(VLOOKUP($Q21,Theme_Master!$A$4:$C$22,3,FALSE()),"")) | U21: =IF($B21="","",IFERROR(VLOOKUP($B21,顧客マスタ!$A$4:$E$15,5,FALSE()),""))
C22: =IF($B22="","",IFERROR(VLOOKUP($B22,顧客マスタ!$A$4:$F$15,2,FALSE()),"")) | I22: =IF($G22="","",TEXT($G22,"yyyy-mm")) | K22: =IF($A22="","",SUMIFS(外注管理!$I$4:$I$60,外注管理!$B$4:$B$60,$A22)) | M22: =IF($J22="","",J22-K22) | N22: =IF(OR($J22="",$J22=0),"",M22/J22) | O22: =IF(OR($L22="",$L22=0),"",ROUND(M22/L22,0)) | R22: =IF($Q22="","",IFERROR(VLOOKUP($Q22,Theme_Master!$A$4:$B$22,2,FALSE()),"")) | T22: =IF($Q22="","",IFERROR(VLOOKUP($Q22,Theme_Master!$A$4:$C$22,3,FALSE()),"")) | U22: =IF($B22="","",IFERROR(VLOOKUP($B22,顧客マスタ!$A$4:$E$15,5,FALSE()),""))
... C60: =IF($B60="","",IFERROR(VLOOKUP($B60,顧客マスタ!$A$4:$F$15,2,FALSE()),"")) | I60: =IF($G60="","",TEXT($G60,"yyyy-mm")) | K60: =IF($A60="","",SUMIFS(外注管理!$I$4:$I$60,外注管理!$B$4:$B$60,$A60)) | M60: =IF($J60="","",J60-K60) | N60: =IF(OR($J60="",$J60=0),"",M60/J60) | O60: =IF(OR($L60="",$L60=0),"",ROUND(M60/L60,0)) | R60: =IF($Q60="","",IFERROR(VLOOKUP($Q60,Theme_Master!$A$4:$B$22,2,FALSE()),"")) | T60: =IF($Q60="","",IFERROR(VLOOKUP($Q60,Theme_Master!$A$4:$C$22,3,FALSE()),"")) | U60: =IF($B60="","",IFERROR(VLOOKUP($B60,顧客マスタ!$A$4:$E$15,5,FALSE()),""))

Sheet 外注管理
A1: 外注管理
A2: 外注費は案件IDをキーに『案件別収益』へ自動集計。
A3: 外注ID | B3: 案件ID | C3: 外注先 | D3: 作業内容 | E3: 発注日 | F3: 納期 | G3: 単価 | H3: 数量 | I3: 外注費 | J3: 支払 | K3: 備考
A4: O001 | B4: J004 | C4: 外注Aさん | D4: 展開作業10点 | E4: 46179 | F4: 46182 | G4: 1000 | H4: 10 | I4: =G4*H4 -> 10000 | J4: 支払済 | K4: サイズ展開
A5: O002 | B5: J005 | C5: 外注Bさん | D5: バナー量産8点 | E5: 46189 | F5: 46192 | G5: 1500 | H5: 8 | I5: =G5*H5 -> 12000 | J5: 未払 | K5: SNS用
I6: =IF($G6="","",G6*H6)
I7: =IF($G7="","",G7*H7)
I8: =IF($G8="","",G8*H8)
I9: =IF($G9="","",G9*H9)
I10: =IF($G10="","",G10*H10)
I11: =IF($G11="","",G11*H11)
I12: =IF($G12="","",G12*H12)
I13: =IF($G13="","",G13*H13)
I14: =IF($G14="","",G14*H14)
I15: =IF($G15="","",G15*H15)
I16: =IF($G16="","",G16*H16)
I17: =IF($G17="","",G17*H17)
... I60: =IF($G60="","",G60*H60)

Sheet 請求管理
A1: 請求管理
A2: 案件IDをキーに顧客・店舗を自動取得。入金管理の参照元。
A3: 請求番号 | B3: 案件ID | C3: 顧客ID | D3: 店舗名 | E3: 請求日 | F3: 請求額(税抜) | G3: 消費税 | H3: 請求合計(税込) | I3: 支払期限 | J3: ステータス | K3: 追加項目(任意) | L3: 追加金額
A4: INV-2026-001 | B4: J004 | C4: =IF($B4="","",IFERROR(VLOOKUP($B4,案件別収益!$A$4:$C$60,2,FALSE()),"")) -> C003 | D4: =IF($B4="","",IFERROR(VLOOKUP($B4,案件別収益!$A$4:$C$60,3,FALSE()),"")) -> □□会館 | E4: 46185 | F4: 150000 | G4: =IF($F4="","",ROUND((F4+IF($K4="",0,L4))*料金マスタ!$B$29,0)) -> 15000 | H4: =IF($F4="","",F4+IF($K4="",0,L4)+G4) -> 165000 | I4: 46234 | J4: 入金済 | L4: =IF($K4="","",IFERROR(VLOOKUP($K4,Pricing_Master!$B$4:$D$22,2,FALSE()),0))
A5: INV-2026-002 | B5: J007 | C5: =IF($B5="","",IFERROR(VLOOKUP($B5,案件別収益!$A$4:$C$60,2,FALSE()),"")) -> C003 | D5: =IF($B5="","",IFERROR(VLOOKUP($B5,案件別収益!$A$4:$C$60,3,FALSE()),"")) -> □□会館 | E5: 46173 | F5: 160000 | G5: =IF($F5="","",ROUND((F5+IF($K5="",0,L5))*料金マスタ!$B$29,0)) -> 16000 | H5: =IF($F5="","",F5+IF($K5="",0,L5)+G5) -> 176000 | I5: 46203 | J5: 入金済 | L5: =IF($K5="","",IFERROR(VLOOKUP($K5,Pricing_Master!$B$4:$D$22,2,FALSE()),0))
A6: INV-2026-003 | B6: J006 | C6: =IF($B6="","",IFERROR(VLOOKUP($B6,案件別収益!$A$4:$C$60,2,FALSE()),"")) -> C001 | D6: =IF($B6="","",IFERROR(VLOOKUP($B6,案件別収益!$A$4:$C$60,3,FALSE()),"")) -> パーラー〇〇 本店 | E6: 46173 | F6: 100000 | G6: =IF($F6="","",ROUND((F6+IF($K6="",0,L6))*料金マスタ!$B$29,0)) -> 10000 | H6: =IF($F6="","",F6+IF($K6="",0,L6)+G6) -> 110000 | I6: 46203 | J6: 請求済 | L6: =IF($K6="","",IFERROR(VLOOKUP($K6,Pricing_Master!$B$4:$D$22,2,FALSE()),0))
A7: INV-2026-004 | B7: J001 | C7: =IF($B7="","",IFERROR(VLOOKUP($B7,案件別収益!$A$4:$C$60,2,FALSE()),"")) -> C003 | D7: =IF($B7="","",IFERROR(VLOOKUP($B7,案件別収益!$A$4:$C$60,3,FALSE()),"")) -> □□会館 | E7: 46203 | F7: 160000 | G7: =IF($F7="","",ROUND((F7+IF($K7="",0,L7))*料金マスタ!$B$29,0)) -> 16000 | H7: =IF($F7="","",F7+IF($K7="",0,L7)+G7) -> 176000 | I7: 46234 | J7: 請求済 | L7: =IF($K7="","",IFERROR(VLOOKUP($K7,Pricing_Master!$B$4:$D$22,2,FALSE()),0))
A8: INV-2026-005 | B8: J002 | C8: =IF($B8="","",IFERROR(VLOOKUP($B8,案件別収益!$A$4:$C$60,2,FALSE()),"")) -> C001 | D8: =IF($B8="","",IFERROR(VLOOKUP($B8,案件別収益!$A$4:$C$60,3,FALSE()),"")) -> パーラー〇〇 本店 | E8: 46203 | F8: 100000 | G8: =IF($F8="","",ROUND((F8+IF($K8="",0,L8))*料金マスタ!$B$29,0)) -> 10000 | H8: =IF($F8="","",F8+IF($K8="",0,L8)+G8) -> 110000 | I8: 46234 | J8: 請求済 | L8: =IF($K8="","",IFERROR(VLOOKUP($K8,Pricing_Master!$B$4:$D$22,2,FALSE()),0))
C9: =IF($B9="","",IFERROR(VLOOKUP($B9,案件別収益!$A$4:$C$60,2,FALSE()),"")) | D9: =IF($B9="","",IFERROR(VLOOKUP($B9,案件別収益!$A$4:$C$60,3,FALSE()),"")) | G9: =IF($F9="","",ROUND((F9+IF($K9="",0,L9))*料金マスタ!$B$29,0)) | H9: =IF($F9="","",F9+IF($K9="",0,L9)+G9) | L9: =IF($K9="","",IFERROR(VLOOKUP($K9,Pricing_Master!$B$4:$D$22,2,FALSE()),0))
C10: =IF($B10="","",IFERROR(VLOOKUP($B10,案件別収益!$A$4:$C$60,2,FALSE()),"")) | D10: =IF($B10="","",IFERROR(VLOOKUP($B10,案件別収益!$A$4:$C$60,3,FALSE()),"")) | G10: =IF($F10="","",ROUND((F10+IF($K10="",0,L10))*料金マスタ!$B$29,0)) | H10: =IF($F10="","",F10+IF($K10="",0,L10)+G10) | L10: =IF($K10="","",IFERROR(VLOOKUP($K10,Pricing_Master!$B$4:$D$22,2,FALSE()),0))
C11: =IF($B11="","",IFERROR(VLOOKUP($B11,案件別収益!$A$4:$C$60,2,FALSE()),"")) | D11: =IF($B11="","",IFERROR(VLOOKUP($B11,案件別収益!$A$4:$C$60,3,FALSE()),"")) | G11: =IF($F11="","",ROUND((F11+IF($K11="",0,L11))*料金マスタ!$B$29,0)) | H11: =IF($F11="","",F11+IF($K11="",0,L11)+G11) | L11: =IF($K11="","",IFERROR(VLOOKUP($K11,Pricing_Master!$B$4:$D$22,2,FALSE()),0))
C12: =IF($B12="","",IFERROR(VLOOKUP($B12,案件別収益!$A$4:$C$60,2,FALSE()),"")) | D12: =IF($B12="","",IFERROR(VLOOKUP($B12,案件別収益!$A$4:$C$60,3,FALSE()),"")) | G12: =IF($F12="","",ROUND((F12+IF($K12="",0,L12))*料金マスタ!$B$29,0)) | H12: =IF($F12="","",F12+IF($K12="",0,L12)+G12) | L12: =IF($K12="","",IFERROR(VLOOKUP($K12,Pricing_Master!$B$4:$D$22,2,FALSE()),0))
C13: =IF($B13="","",IFERROR(VLOOKUP($B13,案件別収益!$A$4:$C$60,2,FALSE()),"")) | D13: =IF($B13="","",IFERROR(VLOOKUP($B13,案件別収益!$A$4:$C$60,3,FALSE()),"")) | G13: =IF($F13="","",ROUND((F13+IF($K13="",0,L13))*料金マスタ!$B$29,0)) | H13: =IF($F13="","",F13+IF($K13="",0,L13)+G13) | L13: =IF($K13="","",IFERROR(VLOOKUP($K13,Pricing_Master!$B$4:$D$22,2,FALSE()),0))
C14: =IF($B14="","",IFERROR(VLOOKUP($B14,案件別収益!$A$4:$C$60,2,FALSE()),"")) | D14: =IF($B14="","",IFERROR(VLOOKUP($B14,案件別収益!$A$4:$C$60,3,FALSE()),"")) | G14: =IF($F14="","",ROUND((F14+IF($K14="",0,L14))*料金マスタ!$B$29,0)) | H14: =IF($F14="","",F14+IF($K14="",0,L14)+G14) | L14: =IF($K14="","",IFERROR(VLOOKUP($K14,Pricing_Master!$B$4:$D$22,2,FALSE()),0))
C15: =IF($B15="","",IFERROR(VLOOKUP($B15,案件別収益!$A$4:$C$60,2,FALSE()),"")) | D15: =IF($B15="","",IFERROR(VLOOKUP($B15,案件別収益!$A$4:$C$60,3,FALSE()),"")) | G15: =IF($F15="","",ROUND((F15+IF($K15="",0,L15))*料金マスタ!$B$29,0)) | H15: =IF($F15="","",F15+IF($K15="",0,L15)+G15) | L15: =IF($K15="","",IFERROR(VLOOKUP($K15,Pricing_Master!$B$4:$D$22,2,FALSE()),0))
C16: =IF($B16="","",IFERROR(VLOOKUP($B16,案件別収益!$A$4:$C$60,2,FALSE()),"")) | D16: =IF($B16="","",IFERROR(VLOOKUP($B16,案件別収益!$A$4:$C$60,3,FALSE()),"")) | G16: =IF($F16="","",ROUND((F16+IF($K16="",0,L16))*料金マスタ!$B$29,0)) | H16: =IF($F16="","",F16+IF($K16="",0,L16)+G16) | L16: =IF($K16="","",IFERROR(VLOOKUP($K16,Pricing_Master!$B$4:$D$22,2,FALSE()),0))
C17: =IF($B17="","",IFERROR(VLOOKUP($B17,案件別収益!$A$4:$C$60,2,FALSE()),"")) | D17: =IF($B17="","",IFERROR(VLOOKUP($B17,案件別収益!$A$4:$C$60,3,FALSE()),"")) | G17: =IF($F17="","",ROUND((F17+IF($K17="",0,L17))*料金マスタ!$B$29,0)) | H17: =IF($F17="","",F17+IF($K17="",0,L17)+G17) | L17: =IF($K17="","",IFERROR(VLOOKUP($K17,Pricing_Master!$B$4:$D$22,2,FALSE()),0))
C18: =IF($B18="","",IFERROR(VLOOKUP($B18,案件別収益!$A$4:$C$60,2,FALSE()),"")) | D18: =IF($B18="","",IFERROR(VLOOKUP($B18,案件別収益!$A$4:$C$60,3,FALSE()),"")) | G18: =IF($F18="","",ROUND((F18+IF($K18="",0,L18))*料金マスタ!$B$29,0)) | H18: =IF($F18="","",F18+IF($K18="",0,L18)+G18) | L18: =IF($K18="","",IFERROR(VLOOKUP($K18,Pricing_Master!$B$4:$D$22,2,FALSE()),0))
C19: =IF($B19="","",IFERROR(VLOOKUP($B19,案件別収益!$A$4:$C$60,2,FALSE()),"")) | D19: =IF($B19="","",IFERROR(VLOOKUP($B19,案件別収益!$A$4:$C$60,3,FALSE()),"")) | G19: =IF($F19="","",ROUND((F19+IF($K19="",0,L19))*料金マスタ!$B$29,0)) | H19: =IF($F19="","",F19+IF($K19="",0,L19)+G19) | L19: =IF($K19="","",IFERROR(VLOOKUP($K19,Pricing_Master!$B$4:$D$22,2,FALSE()),0))
C20: =IF($B20="","",IFERROR(VLOOKUP($B20,案件別収益!$A$4:$C$60,2,FALSE()),"")) | D20: =IF($B20="","",IFERROR(VLOOKUP($B20,案件別収益!$A$4:$C$60,3,FALSE()),"")) | G20: =IF($F20="","",ROUND((F20+IF($K20="",0,L20))*料金マスタ!$B$29,0)) | H20: =IF($F20="","",F20+IF($K20="",0,L20)+G20) | L20: =IF($K20="","",IFERROR(VLOOKUP($K20,Pricing_Master!$B$4:$D$22,2,FALSE()),0))
... C60: =IF($B60="","",IFERROR(VLOOKUP($B60,案件別収益!$A$4:$C$60,2,FALSE()),"")) | D60: =IF($B60="","",IFERROR(VLOOKUP($B60,案件別収益!$A$4:$C$60,3,FALSE()),"")) | G60: =IF($F60="","",ROUND((F60+IF($K60="",0,L60))*料金マスタ!$B$29,0)) | H60: =IF($F60="","",F60+IF($K60="",0,L60)+G60) | L60: =IF($K60="","",IFERROR(VLOOKUP($K60,Pricing_Master!$B$4:$D$22,2,FALSE()),0))

Sheet 入金管理
A1: 入金管理
A2: 請求番号をキーに自動参照。延滞を自動判定。
A3: 請求番号 | B3: 店舗名 | C3: 請求合計 | D3: 支払期限 | E3: 入金日 | F3: 入金額 | G3: 差額 | H3: 状態
A4: INV-2026-001 | B4: =IF($A4="","",IFERROR(VLOOKUP($A4,請求管理!$A$4:$J$60,4,FALSE()),"")) -> □□会館 | C4: =IF($A4="","",IFERROR(VLOOKUP($A4,請求管理!$A$4:$J$60,8,FALSE()),"")) -> 165000 | D4: =IF($A4="","",IFERROR(VLOOKUP($A4,請求管理!$A$4:$J$60,9,FALSE()),"")) -> 46234 | E4: 46223 | F4: 150000 | G4: =IF($A4="","",C4-F4) -> 15000 | H4: =IF($A4="","",IF($E4<>"","入金済",IF($D4<TODAY(),"延滞","未入金"))) -> 入金済
A5: INV-2026-002 | B5: =IF($A5="","",IFERROR(VLOOKUP($A5,請求管理!$A$4:$J$60,4,FALSE()),"")) -> □□会館 | C5: =IF($A5="","",IFERROR(VLOOKUP($A5,請求管理!$A$4:$J$60,8,FALSE()),"")) -> 176000 | D5: =IF($A5="","",IFERROR(VLOOKUP($A5,請求管理!$A$4:$J$60,9,FALSE()),"")) -> 46203 | E5: 46198 | F5: 160000 | G5: =IF($A5="","",C5-F5) -> 16000 | H5: =IF($A5="","",IF($E5<>"","入金済",IF($D5<TODAY(),"延滞","未入金"))) -> 入金済
A6: INV-2026-003 | B6: =IF($A6="","",IFERROR(VLOOKUP($A6,請求管理!$A$4:$J$60,4,FALSE()),"")) -> パーラー〇〇 本店 | C6: =IF($A6="","",IFERROR(VLOOKUP($A6,請求管理!$A$4:$J$60,8,FALSE()),"")) -> 110000 | D6: =IF($A6="","",IFERROR(VLOOKUP($A6,請求管理!$A$4:$J$60,9,FALSE()),"")) -> 46203 | F6: 0 | G6: =IF($A6="","",C6-F6) -> 110000 | H6: =IF($A6="","",IF($E6<>"","入金済",IF($D6<TODAY(),"延滞","未入金"))) -> 未入金
B7: =IF($A7="","",IFERROR(VLOOKUP($A7,請求管理!$A$4:$J$60,4,FALSE()),"")) | C7: =IF($A7="","",IFERROR(VLOOKUP($A7,請求管理!$A$4:$J$60,8,FALSE()),"")) | D7: =IF($A7="","",IFERROR(VLOOKUP($A7,請求管理!$A$4:$J$60,9,FALSE()),"")) | G7: =IF($A7="","",C7-F7) | H7: =IF($A7="","",IF($E7<>"","入金済",IF($D7<TODAY(),"延滞","未入金")))
B8: =IF($A8="","",IFERROR(VLOOKUP($A8,請求管理!$A$4:$J$60,4,FALSE()),"")) | C8: =IF($A8="","",IFERROR(VLOOKUP($A8,請求管理!$A$4:$J$60,8,FALSE()),"")) | D8: =IF($A8="","",IFERROR(VLOOKUP($A8,請求管理!$A$4:$J$60,9,FALSE()),"")) | G8: =IF($A8="","",C8-F8) | H8: =IF($A8="","",IF($E8<>"","入金済",IF($D8<TODAY(),"延滞","未入金")))
B9: =IF($A9="","",IFERROR(VLOOKUP($A9,請求管理!$A$4:$J$60,4,FALSE()),"")) | C9: =IF($A9="","",IFERROR(VLOOKUP($A9,請求管理!$A$4:$J$60,8,FALSE()),"")) | D9: =IF($A9="","",IFERROR(VLOOKUP($A9,請求管理!$A$4:$J$60,9,FALSE()),"")) | G9: =IF($A9="","",C9-F9) | H9: =IF($A9="","",IF($E9<>"","入金済",IF($D9<TODAY(),"延滞","未入金")))
B10: =IF($A10="","",IFERROR(VLOOKUP($A10,請求管理!$A$4:$J$60,4,FALSE()),"")) | C10: =IF($A10="","",IFERROR(VLOOKUP($A10,請求管理!$A$4:$J$60,8,FALSE()),"")) | D10: =IF($A10="","",IFERROR(VLOOKUP($A10,請求管理!$A$4:$J$60,9,FALSE()),"")) | G10: =IF($A10="","",C10-F10) | H10: =IF($A10="","",IF($E10<>"","入金済",IF($D10<TODAY(),"延滞","未入金")))
B11: =IF($A11="","",IFERROR(VLOOKUP($A11,請求管理!$A$4:$J$60,4,FALSE()),"")) | C11: =IF($A11="","",IFERROR(VLOOKUP($A11,請求管理!$A$4:$J$60,8,FALSE()),"")) | D11: =IF($A11="","",IFERROR(VLOOKUP($A11,請求管理!$A$4:$J$60,9,FALSE()),"")) | G11: =IF($A11="","",C11-F11) | H11: =IF($A11="","",IF($E11<>"","入金済",IF($D11<TODAY(),"延滞","未入金")))
B12: =IF($A12="","",IFERROR(VLOOKUP($A12,請求管理!$A$4:$J$60,4,FALSE()),"")) | C12: =IF($A12="","",IFERROR(VLOOKUP($A12,請求管理!$A$4:$J$60,8,FALSE()),"")) | D12: =IF($A12="","",IFERROR(VLOOKUP($A12,請求管理!$A$4:$J$60,9,FALSE()),"")) | G12: =IF($A12="","",C12-F12) | H12: =IF($A12="","",IF($E12<>"","入金済",IF($D12<TODAY(),"延滞","未入金")))
B13: =IF($A13="","",IFERROR(VLOOKUP($A13,請求管理!$A$4:$J$60,4,FALSE()),"")) | C13: =IF($A13="","",IFERROR(VLOOKUP($A13,請求管理!$A$4:$J$60,8,FALSE()),"")) | D13: =IF($A13="","",IFERROR(VLOOKUP($A13,請求管理!$A$4:$J$60,9,FALSE()),"")) | G13: =IF($A13="","",C13-F13) | H13: =IF($A13="","",IF($E13<>"","入金済",IF($D13<TODAY(),"延滞","未入金")))
B14: =IF($A14="","",IFERROR(VLOOKUP($A14,請求管理!$A$4:$J$60,4,FALSE()),"")) | C14: =IF($A14="","",IFERROR(VLOOKUP($A14,請求管理!$A$4:$J$60,8,FALSE()),"")) | D14: =IF($A14="","",IFERROR(VLOOKUP($A14,請求管理!$A$4:$J$60,9,FALSE()),"")) | G14: =IF($A14="","",C14-F14) | H14: =IF($A14="","",IF($E14<>"","入金済",IF($D14<TODAY(),"延滞","未入金")))
B15: =IF($A15="","",IFERROR(VLOOKUP($A15,請求管理!$A$4:$J$60,4,FALSE()),"")) | C15: =IF($A15="","",IFERROR(VLOOKUP($A15,請求管理!$A$4:$J$60,8,FALSE()),"")) | D15: =IF($A15="","",IFERROR(VLOOKUP($A15,請求管理!$A$4:$J$60,9,FALSE()),"")) | G15: =IF($A15="","",C15-F15) | H15: =IF($A15="","",IF($E15<>"","入金済",IF($D15<TODAY(),"延滞","未入金")))
B16: =IF($A16="","",IFERROR(VLOOKUP($A16,請求管理!$A$4:$J$60,4,FALSE()),"")) | C16: =IF($A16="","",IFERROR(VLOOKUP($A16,請求管理!$A$4:$J$60,8,FALSE()),"")) | D16: =IF($A16="","",IFERROR(VLOOKUP($A16,請求管理!$A$4:$J$60,9,FALSE()),"")) | G16: =IF($A16="","",C16-F16) | H16: =IF($A16="","",IF($E16<>"","入金済",IF($D16<TODAY(),"延滞","未入金")))
B17: =IF($A17="","",IFERROR(VLOOKUP($A17,請求管理!$A$4:$J$60,4,FALSE()),"")) | C17: =IF($A17="","",IFERROR(VLOOKUP($A17,請求管理!$A$4:$J$60,8,FALSE()),"")) | D17: =IF($A17="","",IFERROR(VLOOKUP($A17,請求管理!$A$4:$J$60,9,FALSE()),"")) | G17: =IF($A17="","",C17-F17) | H17: =IF($A17="","",IF($E17<>"","入金済",IF($D17<TODAY(),"延滞","未入金")))
B18: =IF($A18="","",IFERROR(VLOOKUP($A18,請求管理!$A$4:$J$60,4,FALSE()),"")) | C18: =IF($A18="","",IFERROR(VLOOKUP($A18,請求管理!$A$4:$J$60,8,FALSE()),"")) | D18: =IF($A18="","",IFERROR(VLOOKUP($A18,請求管理!$A$4:$J$60,9,FALSE()),"")) | G18: =IF($A18="","",C18-F18) | H18: =IF($A18="","",IF($E18<>"","入金済",IF($D18<TODAY(),"延滞","未入金")))
... B40: =IF($A40="","",IFERROR(VLOOKUP($A40,請求管理!$A$4:$J$60,4,FALSE()),"")) | C40: =IF($A40="","",IFERROR(VLOOKUP($A40,請求管理!$A$4:$J$60,8,FALSE()),"")) | D40: =IF($A40="","",IFERROR(VLOOKUP($A40,請求管理!$A$4:$J$60,9,FALSE()),"")) | G40: =IF($A40="","",C40-F40) | H40: =IF($A40="","",IF($E40<>"","入金済",IF($D40<TODAY(),"延滞","未入金")))

Sheet 顧客別収益
A1: 顧客別収益
A2: 顧客ID別に売上・粗利・未収を集計。
A3: 顧客ID | B3: 店舗名 | C3: プラン | D3: 月額 | E3: 売上累計(税抜) | F3: 外注費累計 | G3: 粗利累計 | H3: 粗利率 | I3: 請求累計(税込) | J3: 入金累計 | K3: 未収残 | L3: 案件数 | M3: 通常販促件数 | N3: オープン大型件数 | O3: 特注件数
A4: =IF(顧客マスタ!A4="","",顧客マスタ!A4) -> C001 | B4: =IF(顧客マスタ!B4="","",顧客マスタ!B4) -> パーラー〇〇 本店 | C4: =IF(顧客マスタ!E4="","",顧客マスタ!E4) -> スタンダード | D4: =IF(顧客マスタ!F4="","",顧客マスタ!F4) -> 100000 | E4: =IF($A4="","",SUMIFS(案件別収益!$J$4:$J$60,案件別収益!$B$4:$B$60,$A4)) -> 300000 | F4: =IF($A4="","",SUMIFS(案件別収益!$K$4:$K$60,案件別収益!$B$4:$B$60,$A4)) -> 12000 | G4: =IF($A4="","",E4-F4) -> 288000 | H4: =IF(OR($A4="",E4=0),"",G4/E4) -> 0.96 | I4: =IF($A4="","",SUMIFS(請求管理!$H$4:$H$60,請求管理!$C$4:$C$60,$A4)) -> 220000 | J4: =IF($A4="","",SUMIFS(入金管理!$F$4:$F$40,入金管理!$B$4:$B$40,B4)) -> 0 | K4: =IF($A4="","",I4-J4) -> 220000 | L4: =IF($A4="","",COUNTIFS(案件別収益!$B$4:$B$60,$A4)) -> 3 | M4: =IF($A4="","",COUNTIFS(案件別収益!$B$4:$B$60,$A4,案件別収益!$T$4:$T$60,"通常販促")) -> 0 | N4: =IF($A4="","",COUNTIFS(案件別収益!$B$4:$B$60,$A4,案件別収益!$T$4:$T$60,"オープン・大型")) -> 1 | O4: =IF($A4="","",COUNTIFS(案件別収益!$B$4:$B$60,$A4,案件別収益!$T$4:$T$60,"特注")) -> 0
A5: =IF(顧客マスタ!A5="","",顧客マスタ!A5) -> C002 | B5: =IF(顧客マスタ!B5="","",顧客マスタ!B5) -> △△ホール 駅前店 | C5: =IF(顧客マスタ!E5="","",顧客マスタ!E5) -> ライト | D5: =IF(顧客マスタ!F5="","",顧客マスタ!F5) -> 60000 | E5: =IF($A5="","",SUMIFS(案件別収益!$J$4:$J$60,案件別収益!$B$4:$B$60,$A5)) -> 60000 | F5: =IF($A5="","",SUMIFS(案件別収益!$K$4:$K$60,案件別収益!$B$4:$B$60,$A5)) -> 0 | G5: =IF($A5="","",E5-F5) -> 60000 | H5: =IF(OR($A5="",E5=0),"",G5/E5) -> 1 | I5: =IF($A5="","",SUMIFS(請求管理!$H$4:$H$60,請求管理!$C$4:$C$60,$A5)) -> 0 | J5: =IF($A5="","",SUMIFS(入金管理!$F$4:$F$40,入金管理!$B$4:$B$40,B5)) -> 0 | K5: =IF($A5="","",I5-J5) -> 0 | L5: =IF($A5="","",COUNTIFS(案件別収益!$B$4:$B$60,$A5)) -> 1 | M5: =IF($A5="","",COUNTIFS(案件別収益!$B$4:$B$60,$A5,案件別収益!$T$4:$T$60,"通常販促")) -> 0 | N5: =IF($A5="","",COUNTIFS(案件別収益!$B$4:$B$60,$A5,案件別収益!$T$4:$T$60,"オープン・大型")) -> 0 | O5: =IF($A5="","",COUNTIFS(案件別収益!$B$4:$B$60,$A5,案件別収益!$T$4:$T$60,"特注")) -> 0
A6: =IF(顧客マスタ!A6="","",顧客マスタ!A6) -> C003 | B6: =IF(顧客マスタ!B6="","",顧客マスタ!B6) -> □□会館 | C6: =IF(顧客マスタ!E6="","",顧客マスタ!E6) -> プレミアム | D6: =IF(顧客マスタ!F6="","",顧客マスタ!F6) -> 160000 | E6: =IF($A6="","",SUMIFS(案件別収益!$J$4:$J$60,案件別収益!$B$4:$B$60,$A6)) -> 470000 | F6: =IF($A6="","",SUMIFS(案件別収益!$K$4:$K$60,案件別収益!$B$4:$B$60,$A6)) -> 10000 | G6: =IF($A6="","",E6-F6) -> 460000 | H6: =IF(OR($A6="",E6=0),"",G6/E6) -> 0.9787234 | I6: =IF($A6="","",SUMIFS(請求管理!$H$4:$H$60,請求管理!$C$4:$C$60,$A6)) -> 517000 | J6: =IF($A6="","",SUMIFS(入金管理!$F$4:$F$40,入金管理!$B$4:$B$40,B6)) -> 310000 | K6: =IF($A6="","",I6-J6) -> 207000 | L6: =IF($A6="","",COUNTIFS(案件別収益!$B$4:$B$60,$A6)) -> 3 | M6: =IF($A6="","",COUNTIFS(案件別収益!$B$4:$B$60,$A6,案件別収益!$T$4:$T$60,"通常販促")) -> 0 | N6: =IF($A6="","",COUNTIFS(案件別収益!$B$4:$B$60,$A6,案件別収益!$T$4:$T$60,"オープン・大型")) -> 1 | O6: =IF($A6="","",COUNTIFS(案件別収益!$B$4:$B$60,$A6,案件別収益!$T$4:$T$60,"特注")) -> 0
A7: =IF(顧客マスタ!A7="","",顧客マスタ!A7) -> C004 | B7: =IF(顧客マスタ!B7="","",顧客マスタ!B7) -> ◇◇パチンコ | C7: =IF(顧客マスタ!E7="","",顧客マスタ!E7) -> ライト | D7: =IF(顧客マスタ!F7="","",顧客マスタ!F7) -> 60000 | E7: =IF($A7="","",SUMIFS(案件別収益!$J$4:$J$60,案件別収益!$B$4:$B$60,$A7)) -> 0 | F7: =IF($A7="","",SUMIFS(案件別収益!$K$4:$K$60,案件別収益!$B$4:$B$60,$A7)) -> 0 | G7: =IF($A7="","",E7-F7) -> 0 | H7: =IF(OR($A7="",E7=0),"",G7/E7) | I7: =IF($A7="","",SUMIFS(請求管理!$H$4:$H$60,請求管理!$C$4:$C$60,$A7)) -> 0 | J7: =IF($A7="","",SUMIFS(入金管理!$F$4:$F$40,入金管理!$B$4:$B$40,B7)) -> 0 | K7: =IF($A7="","",I7-J7) -> 0 | L7: =IF($A7="","",COUNTIFS(案件別収益!$B$4:$B$60,$A7)) -> 0 | M7: =IF($A7="","",COUNTIFS(案件別収益!$B$4:$B$60,$A7,案件別収益!$T$4:$T$60,"通常販促")) -> 0 | N7: =IF($A7="","",COUNTIFS(案件別収益!$B$4:$B$60,$A7,案件別収益!$T$4:$T$60,"オープン・大型")) -> 0 | O7: =IF($A7="","",COUNTIFS(案件別収益!$B$4:$B$60,$A7,案件別収益!$T$4:$T$60,"特注")) -> 0
A8: =IF(顧客マスタ!A8="","",顧客マスタ!A8) | B8: =IF(顧客マスタ!B8="","",顧客マスタ!B8) | C8: =IF(顧客マスタ!E8="","",顧客マスタ!E8) | D8: =IF(顧客マスタ!F8="","",顧客マスタ!F8) | E8: =IF($A8="","",SUMIFS(案件別収益!$J$4:$J$60,案件別収益!$B$4:$B$60,$A8)) | F8: =IF($A8="","",SUMIFS(案件別収益!$K$4:$K$60,案件別収益!$B$4:$B$60,$A8)) | G8: =IF($A8="","",E8-F8) | H8: =IF(OR($A8="",E8=0),"",G8/E8) | I8: =IF($A8="","",SUMIFS(請求管理!$H$4:$H$60,請求管理!$C$4:$C$60,$A8)) | J8: =IF($A8="","",SUMIFS(入金管理!$F$4:$F$40,入金管理!$B$4:$B$40,B8)) | K8: =IF($A8="","",I8-J8) | L8: =IF($A8="","",COUNTIFS(案件別収益!$B$4:$B$60,$A8)) | M8: =IF($A8="","",COUNTIFS(案件別収益!$B$4:$B$60,$A8,案件別収益!$T$4:$T$60,"通常販促")) | N8: =IF($A8="","",COUNTIFS(案件別収益!$B$4:$B$60,$A8,案件別収益!$T$4:$T$60,"オープン・大型")) | O8: =IF($A8="","",COUNTIFS(案件別収益!$B$4:$B$60,$A8,案件別収益!$T$4:$T$60,"特注"))
A9: =IF(顧客マスタ!A9="","",顧客マスタ!A9) | B9: =IF(顧客マスタ!B9="","",顧客マスタ!B9) | C9: =IF(顧客マスタ!E9="","",顧客マスタ!E9) | D9: =IF(顧客マスタ!F9="","",顧客マスタ!F9) | E9: =IF($A9="","",SUMIFS(案件別収益!$J$4:$J$60,案件別収益!$B$4:$B$60,$A9)) | F9: =IF($A9="","",SUMIFS(案件別収益!$K$4:$K$60,案件別収益!$B$4:$B$60,$A9)) | G9: =IF($A9="","",E9-F9) | H9: =IF(OR($A9="",E9=0),"",G9/E9) | I9: =IF($A9="","",SUMIFS(請求管理!$H$4:$H$60,請求管理!$C$4:$C$60,$A9)) | J9: =IF($A9="","",SUMIFS(入金管理!$F$4:$F$40,入金管理!$B$4:$B$40,B9)) | K9: =IF($A9="","",I9-J9) | L9: =IF($A9="","",COUNTIFS(案件別収益!$B$4:$B$60,$A9)) | M9: =IF($A9="","",COUNTIFS(案件別収益!$B$4:$B$60,$A9,案件別収益!$T$4:$T$60,"通常販促")) | N9: =IF($A9="","",COUNTIFS(案件別収益!$B$4:$B$60,$A9,案件別収益!$T$4:$T$60,"オープン・大型")) | O9: =IF($A9="","",COUNTIFS(案件別収益!$B$4:$B$60,$A9,案件別収益!$T$4:$T$60,"特注"))
A10: =IF(顧客マスタ!A10="","",顧客マスタ!A10) | B10: =IF(顧客マスタ!B10="","",顧客マスタ!B10) | C10: =IF(顧客マスタ!E10="","",顧客マスタ!E10) | D10: =IF(顧客マスタ!F10="","",顧客マスタ!F10) | E10: =IF($A10="","",SUMIFS(案件別収益!$J$4:$J$60,案件別収益!$B$4:$B$60,$A10)) | F10: =IF($A10="","",SUMIFS(案件別収益!$K$4:$K$60,案件別収益!$B$4:$B$60,$A10)) | G10: =IF($A10="","",E10-F10) | H10: =IF(OR($A10="",E10=0),"",G10/E10) | I10: =IF($A10="","",SUMIFS(請求管理!$H$4:$H$60,請求管理!$C$4:$C$60,$A10)) | J10: =IF($A10="","",SUMIFS(入金管理!$F$4:$F$40,入金管理!$B$4:$B$40,B10)) | K10: =IF($A10="","",I10-J10) | L10: =IF($A10="","",COUNTIFS(案件別収益!$B$4:$B$60,$A10)) | M10: =IF($A10="","",COUNTIFS(案件別収益!$B$4:$B$60,$A10,案件別収益!$T$4:$T$60,"通常販促")) | N10: =IF($A10="","",COUNTIFS(案件別収益!$B$4:$B$60,$A10,案件別収益!$T$4:$T$60,"オープン・大型")) | O10: =IF($A10="","",COUNTIFS(案件別収益!$B$4:$B$60,$A10,案件別収益!$T$4:$T$60,"特注"))
A11: =IF(顧客マスタ!A11="","",顧客マスタ!A11) | B11: =IF(顧客マスタ!B11="","",顧客マスタ!B11) | C11: =IF(顧客マスタ!E11="","",顧客マスタ!E11) | D11: =IF(顧客マスタ!F11="","",顧客マスタ!F11) | E11: =IF($A11="","",SUMIFS(案件別収益!$J$4:$J$60,案件別収益!$B$4:$B$60,$A11)) | F11: =IF($A11="","",SUMIFS(案件別収益!$K$4:$K$60,案件別収益!$B$4:$B$60,$A11)) | G11: =IF($A11="","",E11-F11) | H11: =IF(OR($A11="",E11=0),"",G11/E11) | I11: =IF($A11="","",SUMIFS(請求管理!$H$4:$H$60,請求管理!$C$4:$C$60,$A11)) | J11: =IF($A11="","",SUMIFS(入金管理!$F$4:$F$40,入金管理!$B$4:$B$40,B11)) | K11: =IF($A11="","",I11-J11) | L11: =IF($A11="","",COUNTIFS(案件別収益!$B$4:$B$60,$A11)) | M11: =IF($A11="","",COUNTIFS(案件別収益!$B$4:$B$60,$A11,案件別収益!$T$4:$T$60,"通常販促")) | N11: =IF($A11="","",COUNTIFS(案件別収益!$B$4:$B$60,$A11,案件別収益!$T$4:$T$60,"オープン・大型")) | O11: =IF($A11="","",COUNTIFS(案件別収益!$B$4:$B$60,$A11,案件別収益!$T$4:$T$60,"特注"))
A12: =IF(顧客マスタ!A12="","",顧客マスタ!A12) | B12: =IF(顧客マスタ!B12="","",顧客マスタ!B12) | C12: =IF(顧客マスタ!E12="","",顧客マスタ!E12) | D12: =IF(顧客マスタ!F12="","",顧客マスタ!F12) | E12: =IF($A12="","",SUMIFS(案件別収益!$J$4:$J$60,案件別収益!$B$4:$B$60,$A12)) | F12: =IF($A12="","",SUMIFS(案件別収益!$K$4:$K$60,案件別収益!$B$4:$B$60,$A12)) | G12: =IF($A12="","",E12-F12) | H12: =IF(OR($A12="",E12=0),"",G12/E12) | I12: =IF($A12="","",SUMIFS(請求管理!$H$4:$H$60,請求管理!$C$4:$C$60,$A12)) | J12: =IF($A12="","",SUMIFS(入金管理!$F$4:$F$40,入金管理!$B$4:$B$40,B12)) | K12: =IF($A12="","",I12-J12) | L12: =IF($A12="","",COUNTIFS(案件別収益!$B$4:$B$60,$A12)) | M12: =IF($A12="","",COUNTIFS(案件別収益!$B$4:$B$60,$A12,案件別収益!$T$4:$T$60,"通常販促")) | N12: =IF($A12="","",COUNTIFS(案件別収益!$B$4:$B$60,$A12,案件別収益!$T$4:$T$60,"オープン・大型")) | O12: =IF($A12="","",COUNTIFS(案件別収益!$B$4:$B$60,$A12,案件別収益!$T$4:$T$60,"特注"))
A13: =IF(顧客マスタ!A13="","",顧客マスタ!A13) | B13: =IF(顧客マスタ!B13="","",顧客マスタ!B13) | C13: =IF(顧客マスタ!E13="","",顧客マスタ!E13) | D13: =IF(顧客マスタ!F13="","",顧客マスタ!F13) | E13: =IF($A13="","",SUMIFS(案件別収益!$J$4:$J$60,案件別収益!$B$4:$B$60,$A13)) | F13: =IF($A13="","",SUMIFS(案件別収益!$K$4:$K$60,案件別収益!$B$4:$B$60,$A13)) | G13: =IF($A13="","",E13-F13) | H13: =IF(OR($A13="",E13=0),"",G13/E13) | I13: =IF($A13="","",SUMIFS(請求管理!$H$4:$H$60,請求管理!$C$4:$C$60,$A13)) | J13: =IF($A13="","",SUMIFS(入金管理!$F$4:$F$40,入金管理!$B$4:$B$40,B13)) | K13: =IF($A13="","",I13-J13) | L13: =IF($A13="","",COUNTIFS(案件別収益!$B$4:$B$60,$A13)) | M13: =IF($A13="","",COUNTIFS(案件別収益!$B$4:$B$60,$A13,案件別収益!$T$4:$T$60,"通常販促")) | N13: =IF($A13="","",COUNTIFS(案件別収益!$B$4:$B$60,$A13,案件別収益!$T$4:$T$60,"オープン・大型")) | O13: =IF($A13="","",COUNTIFS(案件別収益!$B$4:$B$60,$A13,案件別収益!$T$4:$T$60,"特注"))
A14: =IF(顧客マスタ!A14="","",顧客マスタ!A14) | B14: =IF(顧客マスタ!B14="","",顧客マスタ!B14) | C14: =IF(顧客マスタ!E14="","",顧客マスタ!E14) | D14: =IF(顧客マスタ!F14="","",顧客マスタ!F14) | E14: =IF($A14="","",SUMIFS(案件別収益!$J$4:$J$60,案件別収益!$B$4:$B$60,$A14)) | F14: =IF($A14="","",SUMIFS(案件別収益!$K$4:$K$60,案件別収益!$B$4:$B$60,$A14)) | G14: =IF($A14="","",E14-F14) | H14: =IF(OR($A14="",E14=0),"",G14/E14) | I14: =IF($A14="","",SUMIFS(請求管理!$H$4:$H$60,請求管理!$C$4:$C$60,$A14)) | J14: =IF($A14="","",SUMIFS(入金管理!$F$4:$F$40,入金管理!$B$4:$B$40,B14)) | K14: =IF($A14="","",I14-J14) | L14: =IF($A14="","",COUNTIFS(案件別収益!$B$4:$B$60,$A14)) | M14: =IF($A14="","",COUNTIFS(案件別収益!$B$4:$B$60,$A14,案件別収益!$T$4:$T$60,"通常販促")) | N14: =IF($A14="","",COUNTIFS(案件別収益!$B$4:$B$60,$A14,案件別収益!$T$4:$T$60,"オープン・大型")) | O14: =IF($A14="","",COUNTIFS(案件別収益!$B$4:$B$60,$A14,案件別収益!$T$4:$T$60,"特注"))
A15: =IF(顧客マスタ!A15="","",顧客マスタ!A15) | B15: =IF(顧客マスタ!B15="","",顧客マスタ!B15) | C15: =IF(顧客マスタ!E15="","",顧客マスタ!E15) | D15: =IF(顧客マスタ!F15="","",顧客マスタ!F15) | E15: =IF($A15="","",SUMIFS(案件別収益!$J$4:$J$60,案件別収益!$B$4:$B$60,$A15)) | F15: =IF($A15="","",SUMIFS(案件別収益!$K$4:$K$60,案件別収益!$B$4:$B$60,$A15)) | G15: =IF($A15="","",E15-F15) | H15: =IF(OR($A15="",E15=0),"",G15/E15) | I15: =IF($A15="","",SUMIFS(請求管理!$H$4:$H$60,請求管理!$C$4:$C$60,$A15)) | J15: =IF($A15="","",SUMIFS(入金管理!$F$4:$F$40,入金管理!$B$4:$B$40,B15)) | K15: =IF($A15="","",I15-J15) | L15: =IF($A15="","",COUNTIFS(案件別収益!$B$4:$B$60,$A15)) | M15: =IF($A15="","",COUNTIFS(案件別収益!$B$4:$B$60,$A15,案件別収益!$T$4:$T$60,"通常販促")) | N15: =IF($A15="","",COUNTIFS(案件別収益!$B$4:$B$60,$A15,案件別収益!$T$4:$T$60,"オープン・大型")) | O15: =IF($A15="","",COUNTIFS(案件別収益!$B$4:$B$60,$A15,案件別収益!$T$4:$T$60,"特注"))

Sheet テーマ別工数分析
A1: テーマ別工数分析
A2: 左:実施ログ(Theme_Code基点) / 右:Theme_Code別の自動集計。
A3: 日付 | B3: テーマコード | C3: テーマ名 | D3: 顧客ID | E3: 媒体数 | F3: 工数h | G3: 売上(任意) | I3: Theme_Code | J3: テーマ名 | K3: 件数 | L3: 総工数 | M3: 平均工数 | N3: 総売上 | O3: 平均時給
A4: 46175 | B4: T101 | C4: =IF($B4="","",IFERROR(VLOOKUP($B4,Theme_Master!$A$4:$B$22,2,FALSE()),"")) -> 新台入替 | E4: 4 | F4: 4.5 | G4: 0 | I4: T101 | J4: =IFERROR(VLOOKUP(I4,Theme_Master!$A$4:$B$22,2,FALSE()),"") -> 新台入替 | K4: =COUNTIF(テーマ別工数分析!$B$4:$B$60,I4) -> 1 | L4: =SUMIF(テーマ別工数分析!$B$4:$B$60,I4,テーマ別工数分析!$F$4:$F$60) -> 4.5 | M4: =IF(K4=0,"",ROUND(L4/K4,1)) -> 4.5 | N4: =SUMIF(テーマ別工数分析!$B$4:$B$60,I4,テーマ別工数分析!$G$4:$G$60) -> 0 | O4: =IF(L4=0,"",ROUND(N4/L4,0)) -> 0
A5: 46176 | B5: T107 | C5: =IF($B5="","",IFERROR(VLOOKUP($B5,Theme_Master!$A$4:$B$22,2,FALSE()),"")) -> 営業スケジュール | E5: 2 | F5: 2 | G5: 0 | I5: T102 | J5: =IFERROR(VLOOKUP(I5,Theme_Master!$A$4:$B$22,2,FALSE()),"") -> おすすめ機種 | K5: =COUNTIF(テーマ別工数分析!$B$4:$B$60,I5) -> 1 | L5: =SUMIF(テーマ別工数分析!$B$4:$B$60,I5,テーマ別工数分析!$F$4:$F$60) -> 4 | M5: =IF(K5=0,"",ROUND(L5/K5,1)) -> 4 | N5: =SUMIF(テーマ別工数分析!$B$4:$B$60,I5,テーマ別工数分析!$G$4:$G$60) -> 0 | O5: =IF(L5=0,"",ROUND(N5/L5,0)) -> 0
A6: 46178 | B6: T204 | C6: =IF($B6="","",IFERROR(VLOOKUP($B6,Theme_Master!$A$4:$B$22,2,FALSE()),"")) -> リニューアルオープン | E6: 8 | F6: 12 | G6: 150000 | I6: T103 | J6: =IFERROR(VLOOKUP(I6,Theme_Master!$A$4:$B$22,2,FALSE()),"") -> 機種訴求 | K6: =COUNTIF(テーマ別工数分析!$B$4:$B$60,I6) -> 0 | L6: =SUMIF(テーマ別工数分析!$B$4:$B$60,I6,テーマ別工数分析!$F$4:$F$60) -> 0 | M6: =IF(K6=0,"",ROUND(L6/K6,1)) | N6: =SUMIF(テーマ別工数分析!$B$4:$B$60,I6,テーマ別工数分析!$G$4:$G$60) -> 0 | O6: =IF(L6=0,"",ROUND(N6/L6,0))
A7: 46181 | B7: T106 | C7: =IF($B7="","",IFERROR(VLOOKUP($B7,Theme_Master!$A$4:$B$22,2,FALSE()),"")) -> 週末訴求 | E7: 3 | F7: 3 | G7: 0 | I7: T104 | J7: =IFERROR(VLOOKUP(I7,Theme_Master!$A$4:$B$22,2,FALSE()),"") -> 演者来店 | K7: =COUNTIF(テーマ別工数分析!$B$4:$B$60,I7) -> 0 | L7: =SUMIF(テーマ別工数分析!$B$4:$B$60,I7,テーマ別工数分析!$F$4:$F$60) -> 0 | M7: =IF(K7=0,"",ROUND(L7/K7,1)) | N7: =SUMIF(テーマ別工数分析!$B$4:$B$60,I7,テーマ別工数分析!$G$4:$G$60) -> 0 | O7: =IF(L7=0,"",ROUND(N7/L7,0))
A8: 46183 | B8: T102 | C8: =IF($B8="","",IFERROR(VLOOKUP($B8,Theme_Master!$A$4:$B$22,2,FALSE()),"")) -> おすすめ機種 | E8: 4 | F8: 4 | G8: 0 | I8: T105 | J8: =IFERROR(VLOOKUP(I8,Theme_Master!$A$4:$B$22,2,FALSE()),"") -> 景品訴求 | K8: =COUNTIF(テーマ別工数分析!$B$4:$B$60,I8) -> 1 | L8: =SUMIF(テーマ別工数分析!$B$4:$B$60,I8,テーマ別工数分析!$F$4:$F$60) -> 3 | M8: =IF(K8=0,"",ROUND(L8/K8,1)) -> 3 | N8: =SUMIF(テーマ別工数分析!$B$4:$B$60,I8,テーマ別工数分析!$G$4:$G$60) -> 0 | O8: =IF(L8=0,"",ROUND(N8/L8,0)) -> 0
A9: 46188 | B9: T201 | C9: =IF($B9="","",IFERROR(VLOOKUP($B9,Theme_Master!$A$4:$B$22,2,FALSE()),"")) -> 周年 | E9: 6 | F9: 9 | G9: 100000 | I9: T106 | J9: =IFERROR(VLOOKUP(I9,Theme_Master!$A$4:$B$22,2,FALSE()),"") -> 週末訴求 | K9: =COUNTIF(テーマ別工数分析!$B$4:$B$60,I9) -> 1 | L9: =SUMIF(テーマ別工数分析!$B$4:$B$60,I9,テーマ別工数分析!$F$4:$F$60) -> 3 | M9: =IF(K9=0,"",ROUND(L9/K9,1)) -> 3 | N9: =SUMIF(テーマ別工数分析!$B$4:$B$60,I9,テーマ別工数分析!$G$4:$G$60) -> 0 | O9: =IF(L9=0,"",ROUND(N9/L9,0)) -> 0
A10: 46191 | B10: T105 | C10: =IF($B10="","",IFERROR(VLOOKUP($B10,Theme_Master!$A$4:$B$22,2,FALSE()),"")) -> 景品訴求 | E10: 3 | F10: 3 | G10: 0 | I10: T107 | J10: =IFERROR(VLOOKUP(I10,Theme_Master!$A$4:$B$22,2,FALSE()),"") -> 営業スケジュール | K10: =COUNTIF(テーマ別工数分析!$B$4:$B$60,I10) -> 2 | L10: =SUMIF(テーマ別工数分析!$B$4:$B$60,I10,テーマ別工数分析!$F$4:$F$60) -> 4.5 | M10: =IF(K10=0,"",ROUND(L10/K10,1)) -> 2.3 | N10: =SUMIF(テーマ別工数分析!$B$4:$B$60,I10,テーマ別工数分析!$G$4:$G$60) -> 0 | O10: =IF(L10=0,"",ROUND(N10/L10,0)) -> 0
A11: 46193 | B11: T107 | C11: =IF($B11="","",IFERROR(VLOOKUP($B11,Theme_Master!$A$4:$B$22,2,FALSE()),"")) -> 営業スケジュール | E11: 2 | F11: 2.5 | G11: 0 | I11: T108 | J11: =IFERROR(VLOOKUP(I11,Theme_Master!$A$4:$B$22,2,FALSE()),"") -> 取材レポート | K11: =COUNTIF(テーマ別工数分析!$B$4:$B$60,I11) -> 0 | L11: =SUMIF(テーマ別工数分析!$B$4:$B$60,I11,テーマ別工数分析!$F$4:$F$60) -> 0 | M11: =IF(K11=0,"",ROUND(L11/K11,1)) | N11: =SUMIF(テーマ別工数分析!$B$4:$B$60,I11,テーマ別工数分析!$G$4:$G$60) -> 0 | O11: =IF(L11=0,"",ROUND(N11/L11,0))
C12: =IF($B12="","",IFERROR(VLOOKUP($B12,Theme_Master!$A$4:$B$22,2,FALSE()),"")) | I12: T109 | J12: =IFERROR(VLOOKUP(I12,Theme_Master!$A$4:$B$22,2,FALSE()),"") -> 付加価値訴求 | K12: =COUNTIF(テーマ別工数分析!$B$4:$B$60,I12) -> 0 | L12: =SUMIF(テーマ別工数分析!$B$4:$B$60,I12,テーマ別工数分析!$F$4:$F$60) -> 0 | M12: =IF(K12=0,"",ROUND(L12/K12,1)) | N12: =SUMIF(テーマ別工数分析!$B$4:$B$60,I12,テーマ別工数分析!$G$4:$G$60) -> 0 | O12: =IF(L12=0,"",ROUND(N12/L12,0))
C13: =IF($B13="","",IFERROR(VLOOKUP($B13,Theme_Master!$A$4:$B$22,2,FALSE()),"")) | I13: T110 | J13: =IFERROR(VLOOKUP(I13,Theme_Master!$A$4:$B$22,2,FALSE()),"") -> 会員募集 | K13: =COUNTIF(テーマ別工数分析!$B$4:$B$60,I13) -> 0 | L13: =SUMIF(テーマ別工数分析!$B$4:$B$60,I13,テーマ別工数分析!$F$4:$F$60) -> 0 | M13: =IF(K13=0,"",ROUND(L13/K13,1)) | N13: =SUMIF(テーマ別工数分析!$B$4:$B$60,I13,テーマ別工数分析!$G$4:$G$60) -> 0 | O13: =IF(L13=0,"",ROUND(N13/L13,0))
C14: =IF($B14="","",IFERROR(VLOOKUP($B14,Theme_Master!$A$4:$B$22,2,FALSE()),"")) | I14: T111 | J14: =IFERROR(VLOOKUP(I14,Theme_Master!$A$4:$B$22,2,FALSE()),"") -> 店舗設備訴求 | K14: =COUNTIF(テーマ別工数分析!$B$4:$B$60,I14) -> 0 | L14: =SUMIF(テーマ別工数分析!$B$4:$B$60,I14,テーマ別工数分析!$F$4:$F$60) -> 0 | M14: =IF(K14=0,"",ROUND(L14/K14,1)) | N14: =SUMIF(テーマ別工数分析!$B$4:$B$60,I14,テーマ別工数分析!$G$4:$G$60) -> 0 | O14: =IF(L14=0,"",ROUND(N14/L14,0))
C15: =IF($B15="","",IFERROR(VLOOKUP($B15,Theme_Master!$A$4:$B$22,2,FALSE()),"")) | I15: T112 | J15: =IFERROR(VLOOKUP(I15,Theme_Master!$A$4:$B$22,2,FALSE()),"") -> 貯玉・再プレイ訴求 | K15: =COUNTIF(テーマ別工数分析!$B$4:$B$60,I15) -> 0 | L15: =SUMIF(テーマ別工数分析!$B$4:$B$60,I15,テーマ別工数分析!$F$4:$F$60) -> 0 | M15: =IF(K15=0,"",ROUND(L15/K15,1)) | N15: =SUMIF(テーマ別工数分析!$B$4:$B$60,I15,テーマ別工数分析!$G$4:$G$60) -> 0 | O15: =IF(L15=0,"",ROUND(N15/L15,0))
C16: =IF($B16="","",IFERROR(VLOOKUP($B16,Theme_Master!$A$4:$B$22,2,FALSE()),"")) | I16: T113 | J16: =IFERROR(VLOOKUP(I16,Theme_Master!$A$4:$B$22,2,FALSE()),"") -> 店舗人事告知 | K16: =COUNTIF(テーマ別工数分析!$B$4:$B$60,I16) -> 0 | L16: =SUMIF(テーマ別工数分析!$B$4:$B$60,I16,テーマ別工数分析!$F$4:$F$60) -> 0 | M16: =IF(K16=0,"",ROUND(L16/K16,1)) | N16: =SUMIF(テーマ別工数分析!$B$4:$B$60,I16,テーマ別工数分析!$G$4:$G$60) -> 0 | O16: =IF(L16=0,"",ROUND(N16/L16,0))
C17: =IF($B17="","",IFERROR(VLOOKUP($B17,Theme_Master!$A$4:$B$22,2,FALSE()),"")) | I17: T201 | J17: =IFERROR(VLOOKUP(I17,Theme_Master!$A$4:$B$22,2,FALSE()),"") -> 周年 | K17: =COUNTIF(テーマ別工数分析!$B$4:$B$60,I17) -> 1 | L17: =SUMIF(テーマ別工数分析!$B$4:$B$60,I17,テーマ別工数分析!$F$4:$F$60) -> 9 | M17: =IF(K17=0,"",ROUND(L17/K17,1)) -> 9 | N17: =SUMIF(テーマ別工数分析!$B$4:$B$60,I17,テーマ別工数分析!$G$4:$G$60) -> 100000 | O17: =IF(L17=0,"",ROUND(N17/L17,0)) -> 11111
C18: =IF($B18="","",IFERROR(VLOOKUP($B18,Theme_Master!$A$4:$B$22,2,FALSE()),"")) | I18: T202 | J18: =IFERROR(VLOOKUP(I18,Theme_Master!$A$4:$B$22,2,FALSE()),"") -> 創業祭 | K18: =COUNTIF(テーマ別工数分析!$B$4:$B$60,I18) -> 0 | L18: =SUMIF(テーマ別工数分析!$B$4:$B$60,I18,テーマ別工数分析!$F$4:$F$60) -> 0 | M18: =IF(K18=0,"",ROUND(L18/K18,1)) | N18: =SUMIF(テーマ別工数分析!$B$4:$B$60,I18,テーマ別工数分析!$G$4:$G$60) -> 0 | O18: =IF(L18=0,"",ROUND(N18/L18,0))
C19: =IF($B19="","",IFERROR(VLOOKUP($B19,Theme_Master!$A$4:$B$22,2,FALSE()),"")) | I19: T203 | J19: =IFERROR(VLOOKUP(I19,Theme_Master!$A$4:$B$22,2,FALSE()),"") -> リフレッシュオープン | K19: =COUNTIF(テーマ別工数分析!$B$4:$B$60,I19) -> 0 | L19: =SUMIF(テーマ別工数分析!$B$4:$B$60,I19,テーマ別工数分析!$F$4:$F$60) -> 0 | M19: =IF(K19=0,"",ROUND(L19/K19,1)) | N19: =SUMIF(テーマ別工数分析!$B$4:$B$60,I19,テーマ別工数分析!$G$4:$G$60) -> 0 | O19: =IF(L19=0,"",ROUND(N19/L19,0))
C20: =IF($B20="","",IFERROR(VLOOKUP($B20,Theme_Master!$A$4:$B$22,2,FALSE()),"")) | I20: T204 | J20: =IFERROR(VLOOKUP(I20,Theme_Master!$A$4:$B$22,2,FALSE()),"") -> リニューアルオープン | K20: =COUNTIF(テーマ別工数分析!$B$4:$B$60,I20) -> 1 | L20: =SUMIF(テーマ別工数分析!$B$4:$B$60,I20,テーマ別工数分析!$F$4:$F$60) -> 12 | M20: =IF(K20=0,"",ROUND(L20/K20,1)) -> 12 | N20: =SUMIF(テーマ別工数分析!$B$4:$B$60,I20,テーマ別工数分析!$G$4:$G$60) -> 150000 | O20: =IF(L20=0,"",ROUND(N20/L20,0)) -> 12500
C21: =IF($B21="","",IFERROR(VLOOKUP($B21,Theme_Master!$A$4:$B$22,2,FALSE()),"")) | I21: T205 | J21: =IFERROR(VLOOKUP(I21,Theme_Master!$A$4:$B$22,2,FALSE()),"") -> グランドオープン | K21: =COUNTIF(テーマ別工数分析!$B$4:$B$60,I21) -> 0 | L21: =SUMIF(テーマ別工数分析!$B$4:$B$60,I21,テーマ別工数分析!$F$4:$F$60) -> 0 | M21: =IF(K21=0,"",ROUND(L21/K21,1)) | N21: =SUMIF(テーマ別工数分析!$B$4:$B$60,I21,テーマ別工数分析!$G$4:$G$60) -> 0 | O21: =IF(L21=0,"",ROUND(N21/L21,0))
C22: =IF($B22="","",IFERROR(VLOOKUP($B22,Theme_Master!$A$4:$B$22,2,FALSE()),"")) | I22: T999 | J22: =IFERROR(VLOOKUP(I22,Theme_Master!$A$4:$B$22,2,FALSE()),"") -> 特注案件 | K22: =COUNTIF(テーマ別工数分析!$B$4:$B$60,I22) -> 0 | L22: =SUMIF(テーマ別工数分析!$B$4:$B$60,I22,テーマ別工数分析!$F$4:$F$60) -> 0 | M22: =IF(K22=0,"",ROUND(L22/K22,1)) | N22: =SUMIF(テーマ別工数分析!$B$4:$B$60,I22,テーマ別工数分析!$G$4:$G$60) -> 0 | O22: =IF(L22=0,"",ROUND(N22/L22,0))
C23: =IF($B23="","",IFERROR(VLOOKUP($B23,Theme_Master!$A$4:$B$22,2,FALSE()),""))
C24: =IF($B24="","",IFERROR(VLOOKUP($B24,Theme_Master!$A$4:$B$22,2,FALSE()),""))
C25: =IF($B25="","",IFERROR(VLOOKUP($B25,Theme_Master!$A$4:$B$22,2,FALSE()),""))
C26: =IF($B26="","",IFERROR(VLOOKUP($B26,Theme_Master!$A$4:$B$22,2,FALSE()),""))
C27: =IF($B27="","",IFERROR(VLOOKUP($B27,Theme_Master!$A$4:$B$22,2,FALSE()),""))
C28: =IF($B28="","",IFERROR(VLOOKUP($B28,Theme_Master!$A$4:$B$22,2,FALSE()),""))
C29: =IF($B29="","",IFERROR(VLOOKUP($B29,Theme_Master!$A$4:$B$22,2,FALSE()),""))
C30: =IF($B30="","",IFERROR(VLOOKUP($B30,Theme_Master!$A$4:$B$22,2,FALSE()),""))
C31: =IF($B31="","",IFERROR(VLOOKUP($B31,Theme_Master!$A$4:$B$22,2,FALSE()),""))
C32: =IF($B32="","",IFERROR(VLOOKUP($B32,Theme_Master!$A$4:$B$22,2,FALSE()),""))
C33: =IF($B33="","",IFERROR(VLOOKUP($B33,Theme_Master!$A$4:$B$22,2,FALSE()),""))
C34: =IF($B34="","",IFERROR(VLOOKUP($B34,Theme_Master!$A$4:$B$22,2,FALSE()),""))
... C60: =IF($B60="","",IFERROR(VLOOKUP($B60,Theme_Master!$A$4:$B$22,2,FALSE()),""))

Sheet 利益分析
A1: 利益分析
A2: 案件別収益から自動集計。商品別・Theme別・Event別。
A3: ■ 商品別利益分析
A4: 商品 | C4: 件数 | D4: 売上 | E4: 外注費 | F4: 粗利 | G4: 粗利率
A5: ライトプラン | C5: =COUNTIFS(案件別収益!$F$4:$F$60,"リテイナー",案件別収益!$U$4:$U$60,"ライト") -> 1 | D5: =SUMIFS(案件別収益!$J$4:$J$60,案件別収益!$F$4:$F$60,"リテイナー",案件別収益!$U$4:$U$60,"ライト") -> 60000 | E5: =SUMIFS(案件別収益!$K$4:$K$60,案件別収益!$F$4:$F$60,"リテイナー",案件別収益!$U$4:$U$60,"ライト") -> 0 | F5: =D5-E5 -> 60000 | G5: =IF(D5=0,"",F5/D5) -> 1
A6: スタンダードプラン | C6: =COUNTIFS(案件別収益!$F$4:$F$60,"リテイナー",案件別収益!$U$4:$U$60,"スタンダード") -> 2 | D6: =SUMIFS(案件別収益!$J$4:$J$60,案件別収益!$F$4:$F$60,"リテイナー",案件別収益!$U$4:$U$60,"スタンダード") -> 200000 | E6: =SUMIFS(案件別収益!$K$4:$K$60,案件別収益!$F$4:$F$60,"リテイナー",案件別収益!$U$4:$U$60,"スタンダード") -> 0 | F6: =D6-E6 -> 200000 | G6: =IF(D6=0,"",F6/D6) -> 1
A7: プレミアムプラン | C7: =COUNTIFS(案件別収益!$F$4:$F$60,"リテイナー",案件別収益!$U$4:$U$60,"プレミアム") -> 2 | D7: =SUMIFS(案件別収益!$J$4:$J$60,案件別収益!$F$4:$F$60,"リテイナー",案件別収益!$U$4:$U$60,"プレミアム") -> 320000 | E7: =SUMIFS(案件別収益!$K$4:$K$60,案件別収益!$F$4:$F$60,"リテイナー",案件別収益!$U$4:$U$60,"プレミアム") -> 0 | F7: =D7-E7 -> 320000 | G7: =IF(D7=0,"",F7/D7) -> 1
A8: スポット計 | C8: =COUNTIFS(案件別収益!$F$4:$F$60,"スポット") -> 2 | D8: =SUMIFS(案件別収益!$J$4:$J$60,案件別収益!$F$4:$F$60,"スポット") -> 250000 | E8: =SUMIFS(案件別収益!$K$4:$K$60,案件別収益!$F$4:$F$60,"スポット") -> 22000 | F8: =D8-E8 -> 228000 | G8: =IF(D8=0,"",F8/D8) -> 0.912
A10: ■ Theme別利益分析
A11: Theme_Code | B11: テーマ名 | C11: 件数 | D11: 売上 | E11: 外注費 | F11: 粗利 | G11: 工数h | H11: 実質時給
A12: T101 | B12: =IFERROR(VLOOKUP(A12,Theme_Master!$A$4:$B$22,2,FALSE()),"") -> 新台入替 | C12: =COUNTIFS(案件別収益!$Q$4:$Q$60,A12) -> 0 | D12: =SUMIFS(案件別収益!$J$4:$J$60,案件別収益!$Q$4:$Q$60,A12) -> 0 | E12: =SUMIFS(案件別収益!$K$4:$K$60,案件別収益!$Q$4:$Q$60,A12) -> 0 | F12: =SUMIFS(案件別収益!$M$4:$M$60,案件別収益!$Q$4:$Q$60,A12) -> 0 | G12: =SUMIFS(案件別収益!$L$4:$L$60,案件別収益!$Q$4:$Q$60,A12) -> 0 | H12: =IF(G12=0,"",ROUND(F12/G12,0))
A13: T102 | B13: =IFERROR(VLOOKUP(A13,Theme_Master!$A$4:$B$22,2,FALSE()),"") -> おすすめ機種 | C13: =COUNTIFS(案件別収益!$Q$4:$Q$60,A13) -> 0 | D13: =SUMIFS(案件別収益!$J$4:$J$60,案件別収益!$Q$4:$Q$60,A13) -> 0 | E13: =SUMIFS(案件別収益!$K$4:$K$60,案件別収益!$Q$4:$Q$60,A13) -> 0 | F13: =SUMIFS(案件別収益!$M$4:$M$60,案件別収益!$Q$4:$Q$60,A13) -> 0 | G13: =SUMIFS(案件別収益!$L$4:$L$60,案件別収益!$Q$4:$Q$60,A13) -> 0 | H13: =IF(G13=0,"",ROUND(F13/G13,0))
A14: T103 | B14: =IFERROR(VLOOKUP(A14,Theme_Master!$A$4:$B$22,2,FALSE()),"") -> 機種訴求 | C14: =COUNTIFS(案件別収益!$Q$4:$Q$60,A14) -> 0 | D14: =SUMIFS(案件別収益!$J$4:$J$60,案件別収益!$Q$4:$Q$60,A14) -> 0 | E14: =SUMIFS(案件別収益!$K$4:$K$60,案件別収益!$Q$4:$Q$60,A14) -> 0 | F14: =SUMIFS(案件別収益!$M$4:$M$60,案件別収益!$Q$4:$Q$60,A14) -> 0 | G14: =SUMIFS(案件別収益!$L$4:$L$60,案件別収益!$Q$4:$Q$60,A14) -> 0 | H14: =IF(G14=0,"",ROUND(F14/G14,0))
A15: T104 | B15: =IFERROR(VLOOKUP(A15,Theme_Master!$A$4:$B$22,2,FALSE()),"") -> 演者来店 | C15: =COUNTIFS(案件別収益!$Q$4:$Q$60,A15) -> 0 | D15: =SUMIFS(案件別収益!$J$4:$J$60,案件別収益!$Q$4:$Q$60,A15) -> 0 | E15: =SUMIFS(案件別収益!$K$4:$K$60,案件別収益!$Q$4:$Q$60,A15) -> 0 | F15: =SUMIFS(案件別収益!$M$4:$M$60,案件別収益!$Q$4:$Q$60,A15) -> 0 | G15: =SUMIFS(案件別収益!$L$4:$L$60,案件別収益!$Q$4:$Q$60,A15) -> 0 | H15: =IF(G15=0,"",ROUND(F15/G15,0))
A16: T105 | B16: =IFERROR(VLOOKUP(A16,Theme_Master!$A$4:$B$22,2,FALSE()),"") -> 景品訴求 | C16: =COUNTIFS(案件別収益!$Q$4:$Q$60,A16) -> 0 | D16: =SUMIFS(案件別収益!$J$4:$J$60,案件別収益!$Q$4:$Q$60,A16) -> 0 | E16: =SUMIFS(案件別収益!$K$4:$K$60,案件別収益!$Q$4:$Q$60,A16) -> 0 | F16: =SUMIFS(案件別収益!$M$4:$M$60,案件別収益!$Q$4:$Q$60,A16) -> 0 | G16: =SUMIFS(案件別収益!$L$4:$L$60,案件別収益!$Q$4:$Q$60,A16) -> 0 | H16: =IF(G16=0,"",ROUND(F16/G16,0))
A17: T106 | B17: =IFERROR(VLOOKUP(A17,Theme_Master!$A$4:$B$22,2,FALSE()),"") -> 週末訴求 | C17: =COUNTIFS(案件別収益!$Q$4:$Q$60,A17) -> 0 | D17: =SUMIFS(案件別収益!$J$4:$J$60,案件別収益!$Q$4:$Q$60,A17) -> 0 | E17: =SUMIFS(案件別収益!$K$4:$K$60,案件別収益!$Q$4:$Q$60,A17) -> 0 | F17: =SUMIFS(案件別収益!$M$4:$M$60,案件別収益!$Q$4:$Q$60,A17) -> 0 | G17: =SUMIFS(案件別収益!$L$4:$L$60,案件別収益!$Q$4:$Q$60,A17) -> 0 | H17: =IF(G17=0,"",ROUND(F17/G17,0))
A18: T107 | B18: =IFERROR(VLOOKUP(A18,Theme_Master!$A$4:$B$22,2,FALSE()),"") -> 営業スケジュール | C18: =COUNTIFS(案件別収益!$Q$4:$Q$60,A18) -> 0 | D18: =SUMIFS(案件別収益!$J$4:$J$60,案件別収益!$Q$4:$Q$60,A18) -> 0 | E18: =SUMIFS(案件別収益!$K$4:$K$60,案件別収益!$Q$4:$Q$60,A18) -> 0 | F18: =SUMIFS(案件別収益!$M$4:$M$60,案件別収益!$Q$4:$Q$60,A18) -> 0 | G18: =SUMIFS(案件別収益!$L$4:$L$60,案件別収益!$Q$4:$Q$60,A18) -> 0 | H18: =IF(G18=0,"",ROUND(F18/G18,0))
A19: T108 | B19: =IFERROR(VLOOKUP(A19,Theme_Master!$A$4:$B$22,2,FALSE()),"") -> 取材レポート | C19: =COUNTIFS(案件別収益!$Q$4:$Q$60,A19) -> 0 | D19: =SUMIFS(案件別収益!$J$4:$J$60,案件別収益!$Q$4:$Q$60,A19) -> 0 | E19: =SUMIFS(案件別収益!$K$4:$K$60,案件別収益!$Q$4:$Q$60,A19) -> 0 | F19: =SUMIFS(案件別収益!$M$4:$M$60,案件別収益!$Q$4:$Q$60,A19) -> 0 | G19: =SUMIFS(案件別収益!$L$4:$L$60,案件別収益!$Q$4:$Q$60,A19) -> 0 | H19: =IF(G19=0,"",ROUND(F19/G19,0))
A20: T109 | B20: =IFERROR(VLOOKUP(A20,Theme_Master!$A$4:$B$22,2,FALSE()),"") -> 付加価値訴求 | C20: =COUNTIFS(案件別収益!$Q$4:$Q$60,A20) -> 0 | D20: =SUMIFS(案件別収益!$J$4:$J$60,案件別収益!$Q$4:$Q$60,A20) -> 0 | E20: =SUMIFS(案件別収益!$K$4:$K$60,案件別収益!$Q$4:$Q$60,A20) -> 0 | F20: =SUMIFS(案件別収益!$M$4:$M$60,案件別収益!$Q$4:$Q$60,A20) -> 0 | G20: =SUMIFS(案件別収益!$L$4:$L$60,案件別収益!$Q$4:$Q$60,A20) -> 0 | H20: =IF(G20=0,"",ROUND(F20/G20,0))
A21: T110 | B21: =IFERROR(VLOOKUP(A21,Theme_Master!$A$4:$B$22,2,FALSE()),"") -> 会員募集 | C21: =COUNTIFS(案件別収益!$Q$4:$Q$60,A21) -> 0 | D21: =SUMIFS(案件別収益!$J$4:$J$60,案件別収益!$Q$4:$Q$60,A21) -> 0 | E21: =SUMIFS(案件別収益!$K$4:$K$60,案件別収益!$Q$4:$Q$60,A21) -> 0 | F21: =SUMIFS(案件別収益!$M$4:$M$60,案件別収益!$Q$4:$Q$60,A21) -> 0 | G21: =SUMIFS(案件別収益!$L$4:$L$60,案件別収益!$Q$4:$Q$60,A21) -> 0 | H21: =IF(G21=0,"",ROUND(F21/G21,0))
